Workbook

Sheet Claims
A1: PATIENTS NAME | B1: Status | C1: SOC | D1: Paid 1 | E1: Status 1 | F1: Start 2 | G1: Paid 2 | H1: Status 2 | I1: Start 3 | J1: Paid 3 | K1: Status 3 | L1: Start 4 | M1: Paid 4 | N1: Status 4 | O1: Start 5 | P1: Paid 5 | Q1: Status 5 | R1: Start 6 | S1: Paid 6 | T1: Status 6 | U1: Status 7 | V1: HIC/MBI
U2: =IF(OR(E2="a",H2="a",K2="a",N2="a",Q2="a",T2="a"),"a",IF(OR(E2="In Process",H2="In Process",K2="In PRocess",N2="In Process",Q2="In Process",T2="In Process"),"X","")) | V2: 6HT8V20PN53
U3: =IF(OR(E3="a",H3="a",K3="a",N3="a",Q3="a",T3="a"),"a",IF(OR(E3="In Process",H3="In Process",K3="In PRocess",N3="In Process",Q3="In Process",T3="In Process"),"X","")) | V3: 4AT4DA6NP03
U4: =IF(OR(E4="a",H4="a",K4="a",N4="a",Q4="a",T4="a"),"a",IF(OR(E4="In Process",H4="In Process",K4="In PRocess",N4="In Process",Q4="In Process",T4="In Process"),"X","")) | V4: 2QP0MH8FH36
U5: =IF(OR(E5="a",H5="a",K5="a",N5="a",Q5="a",T5="a"),"a",IF(OR(E5="In Process",H5="In Process",K5="In PRocess",N5="In Process",Q5="In Process",T5="In Process"),"X","")) | V5: 7WQ8WM6AX49
U6: =IF(OR(E6="a",H6="a",K6="a",N6="a",Q6="a",T6="a"),"a",IF(OR(E6="In Process",H6="In Process",K6="In PRocess",N6="In Process",Q6="In Process",T6="In Process"),"X","")) | V6: 7QW1VQ9PE20
U7: =IF(OR(E7="a",H7="a",K7="a",N7="a",Q7="a",T7="a"),"a",IF(OR(E7="In Process",H7="In Process",K7="In PRocess",N7="In Process",Q7="In Process",T7="In Process"),"X","")) | V7: 7J80R09CK35
U8: =IF(OR(E8="a",H8="a",K8="a",N8="a",Q8="a",T8="a"),"a",IF(OR(E8="In Process",H8="In Process",K8="In PRocess",N8="In Process",Q8="In Process",T8="In Process"),"X","")) | V8: 3QQ1MT8ER94
U9: =IF(OR(E9="a",H9="a",K9="a",N9="a",Q9="a",T9="a"),"a",IF(OR(E9="In Process",H9="In Process",K9="In PRocess",N9="In Process",Q9="In Process",T9="In Process"),"X","")) | V9: 1F79Y75CU31
U10: =IF(OR(E10="a",H10="a",K10="a",N10="a",Q10="a",T10="a"),"a",IF(OR(E10="In Process",H10="In Process",K10="In PRocess",N10="In Process",Q10="In Process",T10="In Process"),"X","")) | V10: 8YT0CT2EC44
U11: =IF(OR(E11="a",H11="a",K11="a",N11="a",Q11="a",T11="a"),"a",IF(OR(E11="In Process",H11="In Process",K11="In PRocess",N11="In Process",Q11="In Process",T11="In Process"),"X","")) | V11: 5MP2Y03CX88
U12: =IF(OR(E12="a",H12="a",K12="a",N12="a",Q12="a",T12="a"),"a",IF(OR(E12="In Process",H12="In Process",K12="In PRocess",N12="In Process",Q12="In Process",T12="In Process"),"X","")) | V12: 3UW4KQ0NN76
U13: =IF(OR(E13="a",H13="a",K13="a",N13="a",Q13="a",T13="a"),"a",IF(OR(E13="In Process",H13="In Process",K13="In PRocess",N13="In Process",Q13="In Process",T13="In Process"),"X","")) | V13: 5QV1A74DK93
... U49: =IF(OR(E49="a",H49="a",K49="a",N49="a",Q49="a",T49="a"),"a",IF(OR(E49="In Process",H49="In Process",K49="In PRocess",N49="In Process",Q49="In Process",T49="In Process"),"X","")) | V49: 2D39NH5KD34
V50: 2FP7HR1FG74
V51: 6Q33AJ5ED14
V52: 3XF4P81UQ85
V53: 2EN5QC8XW76
V54: 6X31CY7XW19
V55: 9HG3N48DP75
V56: 2KX9TX5YJ14
V57: 9CJ4A03MY74
V58: 7TY8AY8NH44
V59: 8DD0TM7YT45
V60: 3QQ1MT8ER94
V61: 5UF6D59HY42
... V205: 4XC4G77GU95
U206: =IF(OR(E206="a",H206="a",K206="a",N206="a",Q206="a",T206="a"),"a",IF(OR(E206="In Process",H206="In Process",K206="In PRocess",N206="In Process",Q206="In Process",T206="In Process"),"X","")) | V206: 7TY8AY8NH44
U207: =IF(OR(E207="a",H207="a",K207="a",N207="a",Q207="a",T207="a"),"a",IF(OR(E207="In Process",H207="In Process",K207="In PRocess",N207="In Process",Q207="In Process",T207="In Process"),"X","")) | V207: 9DG8PN7VT50
U208: =IF(OR(E208="a",H208="a",K208="a",N208="a",Q208="a",T208="a"),"a",IF(OR(E208="In Process",H208="In Process",K208="In PRocess",N208="In Process",Q208="In Process",T208="In Process"),"X","")) | V208: 7QW1VQ9PE20
U209: =IF(OR(E209="a",H209="a",K209="a",N209="a",Q209="a",T209="a"),"a",IF(OR(E209="In Process",H209="In Process",K209="In PRocess",N209="In Process",Q209="In Process",T209="In Process"),"X","")) | V209: 4NF8QQ3YT27
U210: =IF(OR(E210="a",H210="a",K210="a",N210="a",Q210="a",T210="a"),"a",IF(OR(E210="In Process",H210="In Process",K210="In PRocess",N210="In Process",Q210="In Process",T210="In Process"),"X","")) | V210: 3QX4G53TK85
U211: =IF(OR(E211="a",H211="a",K211="a",N211="a",Q211="a",T211="a"),"a",IF(OR(E211="In Process",H211="In Process",K211="In PRocess",N211="In Process",Q211="In Process",T211="In Process"),"X","")) | V211: 6Q33AJ5ED14
U212: =IF(OR(E212="a",H212="a",K212="a",N212="a",Q212="a",T212="a"),"a",IF(OR(E212="In Process",H212="In Process",K212="In PRocess",N212="In Process",Q212="In Process",T212="In Process"),"X","")) | V212: 8PF2G64RA83
U213: =IF(OR(E213="a",H213="a",K213="a",N213="a",Q213="a",T213="a"),"a",IF(OR(E213="In Process",H213="In Process",K213="In PRocess",N213="In Process",Q213="In Process",T213="In Process"),"X","")) | V213: 2FP7HR1FG74
U214: =IF(OR(E214="a",H214="a",K214="a",N214="a",Q214="a",T214="a"),"a",IF(OR(E214="In Process",H214="In Process",K214="In PRocess",N214="In Process",Q214="In Process",T214="In Process"),"X","")) | V214: 5QV1A74DK93
U215: =IF(OR(E215="a",H215="a",K215="a",N215="a",Q215="a",T215="a"),"a",IF(OR(E215="In Process",H215="In Process",K215="In PRocess",N215="In Process",Q215="In Process",T215="In Process"),"X","")) | V215: 1F79Y75CU31
U216: =IF(OR(E216="a",H216="a",K216="a",N216="a",Q216="a",T216="a"),"a",IF(OR(E216="In Process",H216="In Process",K216="In PRocess",N216="In Process",Q216="In Process",T216="In Process"),"X","")) | V216: 1K89WC2ED58
U217: =IF(OR(E217="a",H217="a",K217="a",N217="a",Q217="a",T217="a"),"a",IF(OR(E217="In Process",H217="In Process",K217="In PRocess",N217="In Process",Q217="In Process",T217="In Process"),"X","")) | V217: 2WX1PP2UV03
... U219: =IF(OR(E219="a",H219="a",K219="a",N219="a",Q219="a",T219="a"),"a",IF(OR(E219="In Process",H219="In Process",K219="In PRocess",N219="In Process",Q219="In Process",T219="In Process"),"X","")) | V219: 1N14KW1RX50
...

Sheet PAYMENTS
A1: DATE | B1: DEPOSIT | C1: AMOUNT | D1: SUSPENSE | E1: TOTAL | F1: NOTES | I1: PAST DUE
A2: November
A3: 45597 | B3: 45601
A4: 45600 | B4: 45602
A5: 45601 | B5: 45603
A6: 45602 | B6: 45604
A7: 45603 | B7: 45607
A8: 45604 | B8: 45608
A9: 45607 | B9: 45609
A10: 45608 | B10: 45610
A11: 45609 | B11: 45611
A12: 45610 | B12: 45614
A13: 45611 | B13: 45615 | C13: 6428.07
A14: 45614 | B14: 45616
A15: 45615 | B15: 45617
A16: 45616 | B16: 45618
A17: 45617 | B17: 45621
A18: 45618 | B18: 45622
A19: 45621 | B19: 45623
A20: 45622 | B20: 45624
A21: 45623 | B21: 45625
A22: 45624 | B22: 45628
A23: 45625 | B23: 45629
A24: Total | C24: =SUM(C3:C23) -> 6428.07
A25: December
A26: 45628 | B26: 45630 | C26: 789.79
A27: 45629 | B27: 45631
A28: 45630 | B28: 45632
A29: 45631 | B29: 45635
A30: 45632 | B30: 45636
A31: 45635 | B31: 45637
A32: 45636 | B32: 45638
A33: 45637 | B33: 45639
A34: 45638 | B34: 45642
A35: 45639 | B35: 45643
A36: 45642 | B36: 45644 | C36: 14118.6
A37: 45643 | B37: 45645
A38: 45644 | B38: 45646
A39: 45645 | B39: 45649 | C39: 1316.32
A40: 45646 | B40: 45650
...

Sheet Payment Summary
A1: PATIENTS NAME | B1: Start Date | C1: Reimb | D1: Paid Date | E1: Notes | F1: HIC/MBI
A2: Kaminsky, Zora | B2: 2/25/2026 | C2: 1189.52 | D2: 46101 | F2: 4PC4VA6QE92
A3: Stone, Marilyn | B3: 2/28/2026 | C3: 256.12 | D3: 46101 | F3: 1RG3C29WG99
A4: Odie, Carl | B4: 2/20/2026 | C4: 4284.73 | D4: 46097 | F4: 5WX5QY2EP60
A5: Presley, Robert | B5: 2/1/2026 | C5: 5818.64 | D5: 46097 | F5: 7QK4DX2CV02
A6: Harris, Charlene | B6: 2/1/2026 | C6: 7171.34 | D6: 46097 | F6: 3GH4H62DE90
A7: Gonzalez Suarez, Reyez | B7: 2/1/2026 | C7: 5652.2 | D7: 46097 | F7: 1WC7RT7FE53
A8: Garcia, Davina | B8: 2/1/2026 | C8: 201.86 | D8: 46097 | F8: 3KG3W51ET18
A9: Chriqui, Maurice | B9: 2/1/2026 | C9: 5201.42 | D9: 46097 | F9: 3FM4C63RT62
A10: Crowder, Mary | B10: 2/1/2026 | C10: 6498.1 | D10: 46077 | F10: 4EM1CV3VV34
A11: Crowder, Mary | B11: 1/11/2026 | C11: 4239.15 | D11: 46070 | F11: 4EM1CV3VV34
A12: Harris, Charlene | B12: 1/8/2026 | C12: 6146.86 | D12: 46070 | F12: 3GH4H62DE90
A13: Chriqui, Maurice | B13: 1/7/2026 | C13: 6402.98 | D13: 46070 | F13: 3FM4C63RT62
... A23: Garcia, Davina | B23: 12/1/2025 | C23: 6257.79 | D23: 46038 | F23: 3KG3W51ET18
A24: Min, Kyung | B24: 10/13/2025 | C24: 3711.73 | D24: 46024 | E24: Adjustment | F24: 2T27G24CF45
A25: Ohkawahira, Hidemi | B25: 10/29/2025 | C25: 670.31 | D25: 46024 | E25: Adjustment | F25: 5QJ1J63EM25
A26: Garcia, Davina | B26: 10/1/2025 | C26: 6257.79 | D26: 46024 | E26: Adjustment | F26: 3KG3W51ET18
A27: Wilson, Anthony | B27: 11/5/2025 | C27: 5248.47 | D27: 46024 | F27: 1EP6GW7UD42
A28: Presley, Robert | B28: 10/29/2025 | C28: 768.36 | D28: 46021 | E28: Adjustment | F28: 7QK4DX2CV02
A29: Haas, Loreen | B29: 10/3/2025 | C29: 2469.15 | D29: 46021 | E29: Adjustment | F29: 7PE1XQ3FD04
A30: Schnabel, Dawn | B30: 11/11/2025 | C30: 5122.38 | D30: 46006 | F30: 7QH2CA8RN15
A31: Presley, Robert | B31: 11/1/2025 | C31: 7683.57 | D31: 46006 | F31: 7QK4DX2CV02
A32: Garcia, Davina | B32: 11/1/2025 | C32: 6212.25 | D32: 46006 | F32: 3KG3W51ET18
A33: Garcia, Davina | B33: 9/1/2025 | C33: 6377.05 | D33: 45945 | F33: 3KG3W51ET18
A34: Zelevyanskaya, Vera | B34: 9/1/2025 | C34: 3525.07 | D34: 45945 | F34: 3RT0HC5TT37
A35: Garcia, Davina | B35: 8/1/2025 | C35: 6428.07 | D35: 45916 | F35: 3KG3W51ET18
A36: Zelevyanskaya, Vera | B36: 8/1/2025 | C36: 6584.4 | D36: 45916 | F36: 3RT0HC5TT37
A37: Zelevyanskaya, Vera | B37: 7/1/2025 | C37: 6428.07 | D37: 45884 | F37: 3RT0HC5TT37
A38: Garcia, Davina | B38: 7/1/2025 | C38: 6584.4 | D38: 45884 | F38: 3KG3W51ET18
A39: Garcia, Davina | B39: 6/1/2025 | C39: 6220.72 | D39: 45853 | F39: 3KG3W51ET18
A40: Presley, Robert | B40: 6/1/2025 | C40: 3266.69 | D40: 45853 | F40: 7QK4DX2CV02
A41: Zelevyanskaya, Vera | B41: 6/1/2025 | C41: 6416.72 | D41: 45853 | F41: 3RT0HC5TT37
... A45: Garcia, Davina | B45: 5/1/2025 | C45: 6428.07 | D45: 45824 | F45: 3KG3W51ET18
A46: Ayala Molina, David | B46: 4/1/2025 | C46: 7742.01 | D46: 45804 | E46: Adjustment | F46: 8JN8X53YE52
A47: Winger, David | B47: 5/1/2025 | C47: 951.49 | D47: 45804 | F47: 9G60PU8KF19
A48: Ayala Molina, David | B48: 5/1/2025 | C48: 1904.15 | D48: 45804 | F48: 8JN8X53YE52
A49: Winger, David | B49: 4/3/2025 | C49: 7371.35 | D49: 45792 | F49: 9G60PU8KF19
A50: Zelevyanskaya, Vera | B50: 4/1/2025 | C50: 6416.72 | D50: 45792 | F50: 3RT0HC5TT37
A51: Presley, Robert | B51: 4/1/2025 | C51: 6416.72 | D51: 45792 | F51: 7QK4DX2CV02
A52: Kharitonov, Alexander | B52: 4/9/2025 | C52: 1497.72 | D52: 45792 | F52: 4WT7F41RU20
...

Sheet Future payment
A1: PATIENTS NAME | B1: Start Date | C1: Reimb | D1: Paid Date | E1: Notes | F1: HIC/MBI

Sheet Future Summary
A1: {=_xlfn.UNIQUE('Future payment'!D:D)} -> Paid Date | D1: Status 1 | F1: {=_xlfn.UNIQUE('Payment Summary'!D:D)} -> Paid Date | I1: Status 2
A2: 0 | B2: =SUMIF('Future payment'!D:D,'Future Summary'!A2,'Future payment'!C:C) -> 0 | C2: =VLOOKUP(A2,PAYMENTS!A:D,3,FALSE) -> #N/A | D2: =IF(ISNA(C2),"",IF(B2=C2,"Equal","Not Equal")) | F2: 46101 | G2: =SUMIF('Payment Summary'!D:D,'Future Summary'!F2,'Payment Summary'!C:C) -> 1445.64 | H2: =VLOOKUP(F2,PAYMENTS!A:C,3,FALSE) -> 1445.64 | I2: =IF(G2=H2,"Equal","Not Equal") -> Equal
B3: =SUMIF('Future payment'!D:D,'Future Summary'!A3,'Future payment'!C:C) -> 0 | C3: =VLOOKUP(A3,PAYMENTS!A:D,3,FALSE) -> #N/A | D3: =IF(ISNA(C3),"",IF(B3=C3,"Equal","Not Equal")) | F3: 46097 | G3: =SUMIF('Payment Summary'!D:D,'Future Summary'!F3,'Payment Summary'!C:C) -> 28330.19 | H3: =VLOOKUP(F3,PAYMENTS!A:C,3,FALSE) -> 25309.69 | I3: =IF(G3=H3,"Equal","Not Equal") -> Not Equal
B4: =SUMIF('Future payment'!D:D,'Future Summary'!A4,'Future payment'!C:C) -> 0 | C4: =VLOOKUP(A4,PAYMENTS!A:D,3,FALSE) -> #N/A | D4: =IF(ISNA(C4),"",IF(B4=C4,"Equal","Not Equal")) | F4: 46077 | G4: =SUMIF('Payment Summary'!D:D,'Future Summary'!F4,'Payment Summary'!C:C) -> 6498.1 | H4: =VLOOKUP(F4,PAYMENTS!A:C,3,FALSE) -> 6498.1 | I4: =IF(G4=H4,"Equal","Not Equal") -> Equal
B5: =SUMIF('Future payment'!D:D,'Future Summary'!A5,'Future payment'!C:C) -> 0 | C5: =VLOOKUP(A5,PAYMENTS!A:D,3,FALSE) -> #N/A | D5: =IF(ISNA(C5),"",IF(B5=C5,"Equal","Not Equal")) | F5: 46070 | G5: =SUMIF('Payment Summary'!D:D,'Future Summary'!F5,'Payment Summary'!C:C) -> 42467.62 | H5: =VLOOKUP(F5,PAYMENTS!A:C,3,FALSE) -> 39447.12 | I5: =IF(G5=H5,"Equal","Not Equal") -> Not Equal
B6: =SUMIF('Future payment'!D:D,'Future Summary'!A6,'Future payment'!C:C) -> 0 | C6: =VLOOKUP(A6,PAYMENTS!A:D,3,FALSE) -> #N/A | D6: =IF(ISNA(C6),"",IF(B6=C6,"Equal","Not Equal")) | F6: 46044 | G6: =SUMIF('Payment Summary'!D:D,'Future Summary'!F6,'Payment Summary'!C:C) -> 1994.93 | H6: =VLOOKUP(F6,PAYMENTS!A:C,3,FALSE) -> 1994.93 | I6: =IF(G6=H6,"Equal","Not Equal") -> Equal
B7: =SUMIF('Future payment'!D:D,'Future Summary'!A7,'Future payment'!C:C) -> 0 | C7: =VLOOKUP(A7,PAYMENTS!A:D,3,FALSE) -> #N/A | D7: =IF(ISNA(C7),"",IF(B7=C7,"Equal","Not Equal")) | F7: 46038 | G7: =SUMIF('Payment Summary'!D:D,'Future Summary'!F7,'Payment Summary'!C:C) -> 28334.28 | H7: =VLOOKUP(F7,PAYMENTS!A:C,3,FALSE) -> 25313.78 | I7: =IF(G7=H7,"Equal","Not Equal") -> Not Equal
B8: =SUMIF('Future payment'!D:D,'Future Summary'!A8,'Future payment'!C:C) -> 0 | C8: =VLOOKUP(A8,PAYMENTS!A:D,3,FALSE) -> #N/A | D8: =IF(ISNA(C8),"",IF(B8=C8,"Equal","Not Equal")) | F8: 46024 | G8: =SUMIF('Payment Summary'!D:D,'Future Summary'!F8,'Payment Summary'!C:C) -> 15888.3 | H8: =VLOOKUP(F8,PAYMENTS!A:C,3,FALSE) -> 4686.43 | I8: =IF(G8=H8,"Equal","Not Equal") -> Not Equal
B9: =SUMIF('Future payment'!D:D,'Future Summary'!A9,'Future payment'!C:C) -> 0 | C9: =VLOOKUP(A9,PAYMENTS!A:D,3,FALSE) -> #N/A | D9: =IF(ISNA(C9),"",IF(B9=C9,"Equal","Not Equal")) | F9: 46021 | G9: =SUMIF('Payment Summary'!D:D,'Future Summary'!F9,'Payment Summary'!C:C) -> 3237.51 | H9: =VLOOKUP(F9,PAYMENTS!A:C,3,FALSE) -> 0 | I9: =IF(G9=H9,"Equal","Not Equal") -> Not Equal
B10: =SUMIF('Future payment'!D:D,'Future Summary'!A10,'Future payment'!C:C) -> 0 | C10: =VLOOKUP(A10,PAYMENTS!A:D,3,FALSE) -> #N/A | D10: =IF(ISNA(C10),"",IF(B10=C10,"Equal","Not Equal")) | F10: 46006 | G10: =SUMIF('Payment Summary'!D:D,'Future Summary'!F10,'Payment Summary'!C:C) -> 19018.2 | H10: =VLOOKUP(F10,PAYMENTS!A:C,3,FALSE) -> 15997.7 | I10: =IF(G10=H10,"Equal","Not Equal") -> Not Equal
B11: =SUMIF('Future payment'!D:D,'Future Summary'!A11,'Future payment'!C:C) -> 0 | C11: =VLOOKUP(A11,PAYMENTS!A:D,3,FALSE) -> #N/A | D11: =IF(ISNA(C11),"",IF(B11=C11,"Equal","Not Equal")) | F11: 45945 | G11: =SUMIF('Payment Summary'!D:D,'Future Summary'!F11,'Payment Summary'!C:C) -> 9902.12 | H11: =VLOOKUP(F11,PAYMENTS!A:C,3,FALSE) -> 9902.12 | I11: =IF(G11=H11,"Equal","Not Equal") -> Equal
B12: =SUMIF('Future payment'!D:D,'Future Summary'!A12,'Future payment'!C:C) -> 0 | C12: =VLOOKUP(A12,PAYMENTS!A:D,3,FALSE) -> #N/A | D12: =IF(ISNA(C12),"",IF(B12=C12,"Equal","Not Equal")) | F12: 45916 | G12: =SUMIF('Payment Summary'!D:D,'Future Summary'!F12,'Payment Summary'!C:C) -> 13012.47 | H12: =VLOOKUP(F12,PAYMENTS!A:C,3,FALSE) -> 13012.47 | I12: =IF(G12=H12,"Equal","Not Equal") -> Equal
B13: =SUMIF('Future payment'!D:D,'Future Summary'!A13,'Future payment'!C:C) -> 0 | C13: =VLOOKUP(A13,PAYMENTS!A:D,3,FALSE) -> #N/A | D13: =IF(ISNA(C13),"",IF(B13=C13,"Equal","Not Equal")) | F13: 45884 | G13: =SUMIF('Payment Summary'!D:D,'Future Summary'!F13,'Payment Summary'!C:C) -> 13012.47 | H13: =VLOOKUP(F13,PAYMENTS!A:C,3,FALSE) -> 13012.47 | I13: =IF(G13=H13,"Equal","Not Equal") -> Equal
B14: =SUMIF('Future payment'!D:D,'Future Summary'!A14,'Future payment'!C:C) -> 0 | C14: =VLOOKUP(A14,PAYMENTS!A:D,3,FALSE) -> #N/A | D14: =IF(ISNA(C14),"",IF(B14=C14,"Equal","Not Equal")) | F14: 45853 | G14: =SUMIF('Payment Summary'!D:D,'Future Summary'!F14,'Payment Summary'!C:C) -> 15904.13 | H14: =VLOOKUP(F14,PAYMENTS!A:C,3,FALSE) -> 15904.13 | I14: =IF(G14=H14,"Equal","Not Equal") -> Equal
... B17: =SUMIF('Future payment'!D:D,'Future Summary'!A17,'Future payment'!C:C) -> 0 | C17: =VLOOKUP(A17,PAYMENTS!A:D,3,FALSE) -> #N/A | D17: =IF(ISNA(C17),"",IF(B17=C17,"Equal","Not Equal")) | F17: 45804 | G17: =SUMIF('Payment Summary'!D:D,'Future Summary'!F17,'Payment Summary'!C:C) -> 10597.65 | H17: =VLOOKUP(F17,PAYMENTS!A:C,3,FALSE) -> 2933.82 | I17: =IF(G17=H17,"Equal","Not Equal") -> Not Equal
B18: =SUMIF(#REF!,#REF!,#REF!) -> #REF! | F18: 45792
B19: =SUMIF(#REF!,#REF!,#REF!) -> #REF! | F19: 45762
B20: =SUMIF(#REF!,#REF!,#REF!) -> #REF! | F20: 45733
B21: =SUMIF(#REF!,#REF!,#REF!) -> #REF! | F21: 45706
B22: =SUMIF(#REF!,#REF!,#REF!) -> #REF! | F22: 45701
B23: =SUMIF(#REF!,#REF!,#REF!) -> #REF! | F23: 45687
B24: =SUMIF(#REF!,#REF!,#REF!) -> #REF! | F24: 45672
B25: =SUMIF(#REF!,#REF!,#REF!) -> #REF! | F25: 45663
B26: =SUMIF(#REF!,#REF!,#REF!) -> #REF! | F26: 45645
B27: =SUMIF(#REF!,#REF!,#REF!) -> #REF! | F27: 45642
B28: =SUMIF(#REF!,#REF!,#REF!) -> #REF! | F28: 45628
B29: =SUMIF(#REF!,#REF!,#REF!) -> #REF! | F29: 45611
... B31: =SUMIF(#REF!,#REF!,#REF!) -> #REF! | F31: 0
B32: =SUMIF(#REF!,#REF!,#REF!) -> #REF!
B33: =SUMIF(#REF!,#REF!,#REF!) -> #REF!
B34: =SUMIF(#REF!,#REF!,#REF!) -> #REF!
B35: =SUMIF(#REF!,#REF!,#REF!) -> #REF!
B36: =SUMIF(#REF!,#REF!,#REF!) -> #REF!
B37: =SUMIF(#REF!,#REF!,#REF!) -> #REF!
B38: =SUMIF(#REF!,#REF!,#REF!) -> #REF!
B39: =SUMIF(#REF!,#REF!,#REF!) -> #REF!
B40: =SUMIF(#REF!,#REF!,#REF!) -> #REF!
B41: =SUMIF(#REF!,#REF!,#REF!) -> #REF!
B42: =SUMIF(#REF!,#REF!,#REF!) -> #REF!

Sheet In Process
A1: PATIENTS NAME | B1: Start Date | C1: Submit Date | D1: Projected Reimb | E1: Projected Paid Date | F1: Notes

Sheet Cap
A1: Year | B1: PS&R | C1: Annual Cap | D1: Cap Amount | E1: Total | F1: Actual Cap | G1: Projected Count | H1: Projected Total | I1: Projected Cap | K1: CCN | L1: A11743
A2: 2024 | B2: 8.7699 | C2: 33494.01 | D2: =B2*C2 -> 293739.12 | E2: 291522.68 | F2: =D2-E2 -> 2216.4383
A3: 2025 | B3: 10.9481 | C3: 34465.34 | D3: =B3*C3 -> 377329.99 | E3: 256572.37 | F3: =D3-E3 -> 120757.62
A4: 2026 | B4: 10.6961 | C4: 35361.44 | D4: =B4*C4 -> 378229.5 | E4: 147214.77 | F4: =D4-E4 -> 231014.73
