Workbook

Sheet Claims FY26
A1: PATIENTS NAME | B1: Status | C1: SOC | D1: DC Status | E1: End Date | F1: Month 1 | G1: Paid 1 | H1: Status 1 | I1: Month2 | J1: Paid 2 | K1: Status 2 | L1: Month3 | M1: Paid 3 | N1: Status 3 | O1: Month4 | P1: Paid 4 | Q1: Status 4 | R1: Month5 | S1: Paid 5 | T1: Status 5 | U1: Month6 | V1: Paid 6 | W1: Status 6 | X1: Month7 | Y1: Paid7 | Z1: Status7 | AA1: Month8 | AB1: Paid8 | AC1: Status8 | AD1: Month9 | AE1: Paid 9 | AF1: Status9 | AG1: Month10 | AH1: PAid10 | AI1: Status10 | AJ1: Month11 | AK1: Paid11 | AL1: Status11 | AM1: Month12 | AN1: Paid12 | AO1: Status12 | AP1: Status 7 | AQ1: HIC/MBI
A2: Haas, Loreen | B2: Approved | C2: 45933 | D2: Active | F2: 45933 | I2: 45962 | L2: 45992 | O2: 46023 | R2: 46054 | U2: 46082 | X2: 46113 | AA2: 46143 | AD2: 46174 | AG2: 46204 | AJ2: 46235 | AM2: 46266 | AQ2: 7PE1XQ3FD04
A3: Min, Kyung | B3: Approved | C3: 45943 | D3: Active | F3: 45943 | I3: 45962 | L3: 45992 | O3: 46023 | R3: 46054 | U3: 46082 | X3: 46113 | AA3: 46143 | AD3: 46174 | AG3: 46204 | AJ3: 46235 | AM3: 46266 | AQ3: 2T27G24CF45
A4: Presley, Robert | B4: Approved | C4: 45959 | D4: Active | F4: 45959 | I4: 45962 | L4: 45992 | O4: 46023 | R4: 46054 | U4: 46082 | X4: 46113 | AA4: 46143 | AD4: 46174 | AG4: 46204 | AJ4: 46235 | AM4: 46266 | AQ4: 7QK4DX2CV02
A5: Ohkawahira, Hidemi | B5: Approved | C5: 45959 | D5: Active | F5: 45959 | I5: 45962 | L5: 45992 | O5: 46023 | R5: 46054 | U5: 46082 | X5: 46113 | AA5: 46143 | AD5: 46174 | AG5: 46204 | AJ5: 46235 | AM5: 46266 | AQ5: 5QJ1J63EM25
A6: Schnabel, Dawn | B6: Approved | C6: 45972 | D6: Active | F6: 45972 | I6: 45992 | L6: 46023 | O6: 46054 | R6: 46082 | U6: 46113 | X6: 46143 | AA6: 46174 | AD6: 46204 | AG6: 46235 | AJ6: 46266 | AQ6: 7QH2CA8RN15
A7: Wilson, Anthony | B7: Approved | C7: 45966 | D7: Active | F7: 45966 | I7: 45992 | L7: 46023 | O7: 46054 | R7: 46082 | U7: 46113 | X7: 46143 | AA7: 46174 | AD7: 46204 | AG7: 46235 | AJ7: 46266 | AQ7: 1EP6GW7UD42
A8: Stewart, Gary | B8: Approved | C8: 45996 | D8: Active | F8: 45996 | I8: 46023 | L8: 46054 | O8: 46082 | R8: 46113 | U8: 46143 | X8: 46174 | AA8: 46204 | AD8: 46235 | AG8: 46266 | AQ8: 1D24QC3CW88
A9: Chriqui, Maurice M | B9: Approved | C9: 46029 | D9: Active | F9: 46029 | I9: 46054 | L9: 46082 | O9: 46113 | R9: 46143 | U9: 46174 | X9: 46204 | AA9: 46235 | AD9: 46266 | AQ9: 3FM4C63RT62
A10: Harris, Charlene | B10: Approved | C10: 46030 | D10: Active | F10: 46030 | I10: 46054 | L10: 46082 | O10: 46113 | R10: 46143 | U10: 46174 | X10: 46204 | AA10: 46235 | AD10: 46266 | AQ10: 3GH4H62DE90
A11: Gonzalez Suarez, Reyez | B11: Approved | C11: 46033 | D11: Active | F11: 46033 | I11: 46054 | L11: 46082 | O11: 46113 | R11: 46143 | U11: 46174 | X11: 46204 | AA11: 46235 | AD11: 46266 | AQ11: 1WC7RT7FE53
A12: Crowder, Mary | B12: Approved | C12: 46033 | D12: Active | F12: 46033 | I12: 46054 | L12: 46082 | O12: 46113 | R12: 46143 | U12: 46174 | X12: 46204 | AA12: 46235 | AD12: 46266 | AQ12: 4EM1CV3VV34
A13: Curling, Ronald | B13: Approved | C13: 46052 | D13: Active | F13: 46052 | I13: 46054 | L13: 46082 | O13: 46113 | R13: 46143 | U13: 46174 | X13: 46204 | AA13: 46235 | AD13: 46266 | AQ13: 5WK2XR5KA97
A14: Thompson, Mariah | B14: Approved | C14: 46050 | D14: Active | F14: 46050 | I14: 46054 | L14: 46082 | O14: 46113 | R14: 46143 | U14: 46174 | X14: 46204 | AA14: 46235 | AD14: 46266 | AQ14: 7PG5TR5RF40
A15: Odie, Carl | B15: Approved | C15: 46073 | D15: Active | F15: 46073 | I15: 46082 | L15: 46113 | O15: 46143 | R15: 46174 | U15: 46204 | X15: 46235 | AA15: 46266 | AQ15: 5WX5QY2EP60
A16: Stone, Marilyn | B16: Approved | C16: 46081 | D16: Active | F16: 46081 | I16: 46082 | L16: 46113 | O16: 46143 | R16: 46174 | U16: 46204 | X16: 46235 | AA16: 46266 | AQ16: 1RG3C29WG99
A17: Kaminsky, Zora M | B17: Approved | C17: 46078 | D17: Active | F17: 46078 | I17: 46082 | L17: 46113 | O17: 46143 | R17: 46174 | U17: 46204 | X17: 46235 | AA17: 46266 | AQ17: 4PC4VA6QE92
A18: Swanson, Joy | B18: Approved | C18: 46084 | D18: Active | F18: 46084 | I18: 46113 | L18: 46143 | O18: 46174 | R18: 46204 | U18: 46235 | X18: 46266 | AQ18: 1QF1RX0NM02
A19: Schifini, Albert | B19: Approved | C19: 46087 | D19: Active | F19: 46087 | I19: 46113 | L19: 46143 | O19: 46174 | R19: 46204 | U19: 46235 | X19: 46266 | AQ19: 8FA6A92AA49
A20: Gaylard, Phyllis | B20: Approved | C20: 46087 | D20: Active | F20: 46087 | I20: 46113 | L20: 46143 | O20: 46174 | R20: 46204 | U20: 46235 | X20: 46266 | AQ20: 6HD7UE9XN71
A21: Ratliff, David E | B21: Approved | C21: 46099 | D21: Active | F21: 46099 | I21: 46113 | L21: 46143 | O21: 46174 | R21: 46204 | U21: 46235 | X21: 46266 | AQ21: 3Y06GJ5AM30
A22: Echarren, Elena | B22: Approved | C22: 46100 | D22: Active | F22: 46100 | I22: 46113 | L22: 46143 | O22: 46174 | R22: 46204 | U22: 46235 | X22: 46266 | AQ22: 9CH0VY4XX23
A23: Moore, Shirlee | B23: Approved | C23: 46105 | D23: Active | F23: 46105 | I23: 46113 | L23: 46143 | O23: 46174 | R23: 46204 | U23: 46235 | X23: 46266 | AQ23: 3CG4Q30XF80
A24: Klaus, Grant G | B24: Approved | C24: 46114 | D24: Active | F24: 46114 | I24: 46143 | L24: 46174 | O24: 46204 | R24: 46235 | U24: 46266 | AQ24: 5J70A90VR19
A25: Gomez Huerta, Francisco | B25: Approved | C25: 46122 | D25: Active | F25: 46122 | I25: 46143 | L25: 46174 | O25: 46204 | R25: 46235 | U25: 46266 | AQ25: 5R93JY1YG92
A26: Hawkins, Thomas | B26: Accepted | C26: 46133 | D26: Active | F26: 46133 | I26: 46143 | L26: 46174 | O26: 46204 | R26: 46235 | U26: 46266 | AQ26: 4CG9HN2KY43

Sheet Claims FY25
A1: PATIENTS NAME | B1: Status | C1: SOC | D1: DC Status | E1: End Date | F1: Month 1 | G1: Paid 1 | H1: Status 1 | I1: Month2 | J1: Paid 2 | K1: Status 2 | L1: Month3 | M1: Paid 3 | N1: Status 3 | O1: Month4 | P1: Paid 4 | Q1: Status 4 | R1: Month5 | S1: Paid 5 | T1: Status 5 | U1: Month6 | V1: Paid 6 | W1: Status 6 | X1: Month7 | Y1: Paid7 | Z1: Status7 | AA1: Month8 | AB1: Paid8 | AC1: Status8 | AD1: Month9 | AE1: Paid 9 | AF1: Status9 | AG1: Month10 | AH1: PAid10 | AI1: Status10 | AJ1: Month11 | AK1: Paid11 | AL1: Status11 | AM1: Month12 | AN1: Paid12 | AO1: Status12 | AP1: Status 7 | AQ1: HIC/MBI
A2: zelevyanskaya, vera | B2: Approved | C2: 45594 | D2: Active | F2: 45594 | I2: 45597 | L2: 45627 | O2: 45658 | R2: 45689 | U2: 45717 | X2: 45748 | AA2: 45778 | AD2: 45809 | AG2: 45839 | AJ2: 45870 | AM2: 45901 | AQ2: 3RT0HC5TT37
A3: tucker, martin | B3: Approved | C3: 45622 | D3: Active | F3: 45622 | I3: 45627 | L3: 45658 | O3: 45689 | R3: 45717 | U3: 45748 | X3: 45778 | AA3: 45809 | AD3: 45839 | AG3: 45870 | AJ3: 45901 | AQ3: 4U81T44EP08
A4: villasenor, carole | B4: Approved | C4: 45630 | D4: Active | F4: 45630 | I4: 45658 | L4: 45689 | O4: 45717 | R4: 45748 | U4: 45778 | X4: 45809 | AA4: 45839 | AD4: 45870 | AG4: 45901 | AQ4: 8K27AY0QJ67
A5: schwartz, sheila | B5: Approved | C5: 45667 | D5: Active | F5: 45667 | I5: 45689 | L5: 45717 | O5: 45748 | R5: 45778 | U5: 45809 | X5: 45839 | AA5: 45870 | AD5: 45901 | AQ5: 6R29G33NQ23
A6: garcia, davina | B6: Approved | C6: 45671 | D6: Active | F6: 45671 | I6: 45689 | L6: 45717 | O6: 45748 | R6: 45778 | U6: 45809 | X6: 45839 | AA6: 45870 | AD6: 45901 | AQ6: 3KG3W51ET18
A7: wacker, ruth | B7: Approved | C7: 45680 | D7: Active | F7: 45680 | I7: 45689 | L7: 45717 | O7: 45748 | R7: 45778 | U7: 45809 | X7: 45839 | AA7: 45870 | AD7: 45901 | AQ7: 8UW5QU7CP77
A8: dixon, guandzale | B8: Approved | C8: 45733 | D8: Active | F8: 45733 | I8: 45748 | L8: 45778 | O8: 45809 | R8: 45839 | U8: 45870 | X8: 45901 | AQ8: 7EH0X57VY14
A9: ayala molina, david | B9: Approved | C9: 45747 | D9: Active | F9: 45747 | I9: 45748 | L9: 45778 | O9: 45809 | R9: 45839 | U9: 45870 | X9: 45901 | AQ9: 8JN8X53YE52
A10: winger, david | B10: Approved | C10: 45750 | D10: Active | F10: 45750 | I10: 45778 | L10: 45809 | O10: 45839 | R10: 45870 | U10: 45901 | AQ10: 9G60PU8KF19
A11: kharitonov, alexander | B11: Approved | C11: 45756 | D11: Active | F11: 45756 | I11: 45778 | L11: 45809 | O11: 45839 | R11: 45870 | U11: 45901 | AQ11: 4WT7F41RU20
A12: bell, clarkson | B12: Approved | C12: 45780 | D12: Active | F12: 45780 | I12: 45809 | L12: 45839 | O12: 45870 | R12: 45901 | AQ12: 8AN6TD7FK77

Sheet PAYMENTS
A1: DATE | B1: DEPOSIT | C1: AMOUNT | D1: SUSPENSE | E1: TOTAL | F1: NOTES | I1: PAST DUE
A2: November
A3: 45597 | B3: 45601
A4: 45600 | B4: 45602
A5: 45601 | B5: 45603
A6: 45602 | B6: 45604
A7: 45603 | B7: 45607
A8: 45604 | B8: 45608
A9: 45607 | B9: 45609
A10: 45608 | B10: 45610
A11: 45609 | B11: 45611
A12: 45610 | B12: 45614
A13: 45611 | B13: 45615 | C13: 6428.07
A14: 45614 | B14: 45616
A15: 45615 | B15: 45617
A16: 45616 | B16: 45618
A17: 45617 | B17: 45621
A18: 45618 | B18: 45622
A19: 45621 | B19: 45623
A20: 45622 | B20: 45624
A21: 45623 | B21: 45625
A22: 45624 | B22: 45628
A23: 45625 | B23: 45629
A24: Total | C24: =SUM(C3:C23) -> 6428.07
A25: December
A26: 45628 | B26: 45630 | C26: 789.79
A27: 45629 | B27: 45631
A28: 45630 | B28: 45632
A29: 45631 | B29: 45635
A30: 45632 | B30: 45636
A31: 45635 | B31: 45637
A32: 45636 | B32: 45638
A33: 45637 | B33: 45639
A34: 45638 | B34: 45642
A35: 45639 | B35: 45643
A36: 45642 | B36: 45644 | C36: 14118.6
A37: 45643 | B37: 45645
A38: 45644 | B38: 45646
A39: 45645 | B39: 45649 | C39: 1316.32
A40: 45646 | B40: 45650
...

Sheet Payment Summary
A1: PATIENTS NAME | B1: Start Date | C1: Reimb | D1: Paid Date | E1: Notes | F1: HIC/MBI
A2: Swanson, Joy | B2: 3/3/2026 | C2: 6786.06 | D2: 46127 | F2: 1QF1RX0NM02
A3: Echarren, Elena | B3: 3/19/2026 | C3: 3329.55 | D3: 46127 | F3: 9CH0VY4XX23
A4: Gaylard, Phyllis | B4: 3/6/2026 | C4: 6564.34 | D4: 46127 | F4: 6HD7UE9XN71
A5: Kaminsky, Zora | B5: 3/1/2026 | C5: 7939.7 | D5: 46127 | F5: 4PC4VA6QE92
A6: Stone, Marilyn | B6: 3/1/2026 | C6: 7939.7 | D6: 46127 | F6: 1RG3C29WG99
A7: Schifini, Albert | B7: 3/6/2026 | C7: 6301.34 | D7: 46127 | F7: 8FA6A92AA49
A8: Moore, Shirlee | B8: 3/24/2026 | C8: 2048.95 | D8: 46127 | F8: 3CG4Q30XF80
A9: Harris, Charlene | B9: 3/1/2026 | C9: 6691.83 | D9: 46127 | F9: 3GH4H62DE90
A10: Kaminsky, Zora | B10: 2/25/2026 | C10: 1189.52 | D10: 46101 | F10: 4PC4VA6QE92
A11: Stone, Marilyn | B11: 2/28/2026 | C11: 256.12 | D11: 46101 | F11: 1RG3C29WG99
A12: Odie, Carl | B12: 2/20/2026 | C12: 4284.73 | D12: 46097 | F12: 5WX5QY2EP60
A13: Presley, Robert | B13: 2/1/2026 | C13: 5818.64 | D13: 46097 | F13: 7QK4DX2CV02
A14: Cap Repayment | C14: -3020.5 | D14: 46097
A15: Harris, Charlene | B15: 2/1/2026 | C15: 7171.34 | D15: 46097 | F15: 3GH4H62DE90
A16: Gonzalez Suarez, Reyez | B16: 2/1/2026 | C16: 5652.2 | D16: 46097 | F16: 1WC7RT7FE53
A17: Garcia, Davina | B17: 2/1/2026 | C17: 201.86 | D17: 46097 | F17: 3KG3W51ET18
A18: Chriqui, Maurice | B18: 2/1/2026 | C18: 5201.42 | D18: 46097 | F18: 3FM4C63RT62
A19: Crowder, Mary | B19: 2/1/2026 | C19: 6498.1 | D19: 46077 | F19: 4EM1CV3VV34
A20: Crowder, Mary | B20: 1/11/2026 | C20: 4239.15 | D20: 46070 | F20: 4EM1CV3VV34
A21: Harris, Charlene | B21: 1/8/2026 | C21: 6146.86 | D21: 46070 | F21: 3GH4H62DE90
A22: Cap Repayment | C22: -3020.5 | D22: 46070
A23: Chriqui, Maurice | B23: 1/7/2026 | C23: 6402.98 | D23: 46070 | F23: 3FM4C63RT62
A24: Presley, Robert | B24: 1/1/2026 | C24: 6257.79 | D24: 46070 | F24: 7QK4DX2CV02
A25: Gonzalez Suarez, Reyez | B25: 1/11/2026 | C25: 4404.2 | D25: 46070 | F25: 1WC7RT7FE53
A26: Schnabel, Dawn | B26: 1/1/2026 | C26: 3516.25 | D26: 46070 | F26: 7QH2CA8RN15
A27: Wilson, Anthony | B27: 1/1/2026 | C27: 5046.6 | D27: 46070 | F27: 1EP6GW7UD42
A28: Garcia, Davina | B28: 1/1/2026 | C28: 6453.79 | D28: 46070 | F28: 3KG3W51ET18
A29: Stewart, Gary | B29: 12/5/2025 | C29: 1994.93 | D29: 46044 | F29: 1D24QC3CW88
A30: Schnabel, Dawn | B30: 12/1/2025 | C30: 7939.7 | D30: 46038 | F30: 7QH2CA8RN15
A31: Cap Repayment | C31: -3020.5 | D31: 46038
A32: Wilson, Anthony | B32: 12/1/2025 | C32: 6257.79 | D32: 46038 | F32: 1EP6GW7UD42
A33: Presley, Robert | B33: 12/1/2025 | C33: 7879 | D33: 46038 | F33: 7QK4DX2CV02
A34: Garcia, Davina | B34: 12/1/2025 | C34: 6257.79 | D34: 46038 | F34: 3KG3W51ET18
A35: Min, Kyung | B35: 10/13/2025 | C35: -150.56 | D35: 46024 | E35: Adjustment | F35: 2T27G24CF45
A36: Ohkawahira, Hidemi | B36: 10/29/2025 | C36: -26 | D36: 46024 | E36: Adjustment | F36: 5QJ1J63EM25
A37: Garcia, Davina | B37: 10/1/2025 | C37: -254.15 | D37: 46024 | E37: Adjustment | F37: 3KG3W51ET18
A38: Wilson, Anthony | B38: 11/5/2025 | C38: 5248.47 | D38: 46024 | F38: 1EP6GW7UD42
A39: Presley, Robert | B39: 10/29/2025 | C39: -31.17 | D39: 46024 | E39: Adjustment | F39: 7QK4DX2CV02
A40: Haas, Loreen | B40: 10/3/2025 | C40: -100.16 | D40: 46024 | E40: Adjustment | F40: 7PE1XQ3FD04
...

Sheet Future payment
A1: PATIENTS NAME | B1: Start Date | C1: Reimb | D1: Paid Date | E1: Notes | F1: HIC/MBI

Sheet Future Summary
A1: {=_xlfn.UNIQUE('Future payment'!D:D)} -> Paid Date | D1: Status 1 | F1: {=_xlfn.UNIQUE('Payment Summary'!D:D)} -> Paid Date | I1: Status 2
A2: 0 | B2: =SUMIF('Future payment'!D:D,'Future Summary'!A2,'Future payment'!C:C) -> 0 | C2: =VLOOKUP(A2,PAYMENTS!A:D,3,FALSE) -> #N/A | D2: =IF(ISNA(C2),"",IF(B2=C2,"Equal","Not Equal")) | F2: 46127 | G2: =SUMIF('Payment Summary'!D:D,'Future Summary'!F2,'Payment Summary'!C:C) -> 47601.47 | H2: =VLOOKUP(F2,PAYMENTS!A:C,3,FALSE) -> 44580.97 | I2: =IF(G2=H2,"Equal","Not Equal") -> Not Equal | L2: =G2-H2 -> 3020.5
B3: =SUMIF('Future payment'!D:D,'Future Summary'!A3,'Future payment'!C:C) -> 0 | C3: =VLOOKUP(A3,PAYMENTS!A:D,3,FALSE) -> #N/A | D3: =IF(ISNA(C3),"",IF(B3=C3,"Equal","Not Equal")) | F3: 46101 | G3: =SUMIF('Payment Summary'!D:D,'Future Summary'!F3,'Payment Summary'!C:C) -> 1445.64 | H3: =VLOOKUP(F3,PAYMENTS!A:C,3,FALSE) -> 1445.64 | I3: =IF(G3=H3,"Equal","Not Equal") -> Equal | L3: =G3-H3 -> 0
B4: =SUMIF('Future payment'!D:D,'Future Summary'!A4,'Future payment'!C:C) -> 0 | C4: =VLOOKUP(A4,PAYMENTS!A:D,3,FALSE) -> #N/A | D4: =IF(ISNA(C4),"",IF(B4=C4,"Equal","Not Equal")) | F4: 46097 | G4: =SUMIF('Payment Summary'!D:D,'Future Summary'!F4,'Payment Summary'!C:C) -> 25309.69 | H4: =VLOOKUP(F4,PAYMENTS!A:C,3,FALSE) -> 25309.69 | I4: =IF(G4=H4,"Equal","Not Equal") -> Equal | L4: =G4-H4 -> 0
B5: =SUMIF('Future payment'!D:D,'Future Summary'!A5,'Future payment'!C:C) -> 0 | C5: =VLOOKUP(A5,PAYMENTS!A:D,3,FALSE) -> #N/A | D5: =IF(ISNA(C5),"",IF(B5=C5,"Equal","Not Equal")) | F5: 46077 | G5: =SUMIF('Payment Summary'!D:D,'Future Summary'!F5,'Payment Summary'!C:C) -> 6498.1 | H5: =VLOOKUP(F5,PAYMENTS!A:C,3,FALSE) -> 6498.1 | I5: =IF(G5=H5,"Equal","Not Equal") -> Equal | L5: =G5-H5 -> 0
B6: =SUMIF('Future payment'!D:D,'Future Summary'!A6,'Future payment'!C:C) -> 0 | C6: =VLOOKUP(A6,PAYMENTS!A:D,3,FALSE) -> #N/A | D6: =IF(ISNA(C6),"",IF(B6=C6,"Equal","Not Equal")) | F6: 46070 | G6: =SUMIF('Payment Summary'!D:D,'Future Summary'!F6,'Payment Summary'!C:C) -> 39447.12 | H6: =VLOOKUP(F6,PAYMENTS!A:C,3,FALSE) -> 39447.12 | I6: =IF(G6=H6,"Equal","Not Equal") -> Equal | L6: =G6-H6 -> 0
B7: =SUMIF('Future payment'!D:D,'Future Summary'!A7,'Future payment'!C:C) -> 0 | C7: =VLOOKUP(A7,PAYMENTS!A:D,3,FALSE) -> #N/A | D7: =IF(ISNA(C7),"",IF(B7=C7,"Equal","Not Equal")) | F7: 46044 | G7: =SUMIF('Payment Summary'!D:D,'Future Summary'!F7,'Payment Summary'!C:C) -> 1994.93 | H7: =VLOOKUP(F7,PAYMENTS!A:C,3,FALSE) -> 1994.93 | I7: =IF(G7=H7,"Equal","Not Equal") -> Equal | L7: =G7-H7 -> 0
B8: =SUMIF('Future payment'!D:D,'Future Summary'!A8,'Future payment'!C:C) -> 0 | C8: =VLOOKUP(A8,PAYMENTS!A:D,3,FALSE) -> #N/A | D8: =IF(ISNA(C8),"",IF(B8=C8,"Equal","Not Equal")) | F8: 46038 | G8: =SUMIF('Payment Summary'!D:D,'Future Summary'!F8,'Payment Summary'!C:C) -> 25313.78 | H8: =VLOOKUP(F8,PAYMENTS!A:C,3,FALSE) -> 25313.78 | I8: =IF(G8=H8,"Equal","Not Equal") -> Equal | L8: =G8-H8 -> 0
B9: =SUMIF('Future payment'!D:D,'Future Summary'!A9,'Future payment'!C:C) -> 0 | C9: =VLOOKUP(A9,PAYMENTS!A:D,3,FALSE) -> #N/A | D9: =IF(ISNA(C9),"",IF(B9=C9,"Equal","Not Equal")) | F9: 46024 | G9: =SUMIF('Payment Summary'!D:D,'Future Summary'!F9,'Payment Summary'!C:C) -> 4686.43 | H9: =VLOOKUP(F9,PAYMENTS!A:C,3,FALSE) -> 4686.43 | I9: =IF(G9=H9,"Equal","Not Equal") -> Equal | L9: =G9-H9 -> 0
B10: =SUMIF('Future payment'!D:D,'Future Summary'!A10,'Future payment'!C:C) -> 0 | C10: =VLOOKUP(A10,PAYMENTS!A:D,3,FALSE) -> #N/A | D10: =IF(ISNA(C10),"",IF(B10=C10,"Equal","Not Equal")) | F10: 46006 | G10: =SUMIF('Payment Summary'!D:D,'Future Summary'!F10,'Payment Summary'!C:C) -> 15997.7 | H10: =VLOOKUP(F10,PAYMENTS!A:C,3,FALSE) -> 15997.7 | I10: =IF(G10=H10,"Equal","Not Equal") -> Equal | L10: =G10-H10 -> 0
B11: =SUMIF('Future payment'!D:D,'Future Summary'!A11,'Future payment'!C:C) -> 0 | C11: =VLOOKUP(A11,PAYMENTS!A:D,3,FALSE) -> #N/A | D11: =IF(ISNA(C11),"",IF(B11=C11,"Equal","Not Equal")) | F11: 45981 | G11: =SUMIF('Payment Summary'!D:D,'Future Summary'!F11,'Payment Summary'!C:C) -> 799.53 | H11: =VLOOKUP(F11,PAYMENTS!A:C,3,FALSE) -> 799.53 | I11: =IF(G11=H11,"Equal","Not Equal") -> Equal | L11: =G11-H11 -> 0
B12: =SUMIF('Future payment'!D:D,'Future Summary'!A12,'Future payment'!C:C) -> 0 | C12: =VLOOKUP(A12,PAYMENTS!A:D,3,FALSE) -> #N/A | D12: =IF(ISNA(C12),"",IF(B12=C12,"Equal","Not Equal")) | F12: 45979 | G12: =SUMIF('Payment Summary'!D:D,'Future Summary'!F12,'Payment Summary'!C:C) -> 697.5 | H12: =VLOOKUP(F12,PAYMENTS!A:C,3,FALSE) -> 697.5 | I12: =IF(G12=H12,"Equal","Not Equal") -> Equal | L12: =G12-H12 -> 0
B13: =SUMIF('Future payment'!D:D,'Future Summary'!A13,'Future payment'!C:C) -> 0 | C13: =VLOOKUP(A13,PAYMENTS!A:D,3,FALSE) -> #N/A | D13: =IF(ISNA(C13),"",IF(B13=C13,"Equal","Not Equal")) | F13: 45978 | G13: =SUMIF('Payment Summary'!D:D,'Future Summary'!F13,'Payment Summary'!C:C) -> 6511.94 | H13: =VLOOKUP(F13,PAYMENTS!A:C,3,FALSE) -> 6511.94 | I13: =IF(G13=H13,"Equal","Not Equal") -> Equal | L13: =G13-H13 -> 0
B14: =SUMIF('Future payment'!D:D,'Future Summary'!A14,'Future payment'!C:C) -> 0 | C14: =VLOOKUP(A14,PAYMENTS!A:D,3,FALSE) -> #N/A | D14: =IF(ISNA(C14),"",IF(B14=C14,"Equal","Not Equal")) | F14: 45968 | G14: =SUMIF('Payment Summary'!D:D,'Future Summary'!F14,'Payment Summary'!C:C) -> 2569.31 | H14: =VLOOKUP(F14,PAYMENTS!A:C,3,FALSE) -> 2569.31 | I14: =IF(G14=H14,"Equal","Not Equal") -> Equal | L14: =G14-H14 -> 0
... B17: =SUMIF('Future payment'!D:D,'Future Summary'!A17,'Future payment'!C:C) -> 0 | C17: =VLOOKUP(A17,PAYMENTS!A:D,3,FALSE) -> #N/A | D17: =IF(ISNA(C17),"",IF(B17=C17,"Equal","Not Equal")) | F17: 45916 | G17: =SUMIF('Payment Summary'!D:D,'Future Summary'!F17,'Payment Summary'!C:C) -> 13012.47 | H17: =VLOOKUP(F17,PAYMENTS!A:C,3,FALSE) -> 13012.47 | I17: =IF(G17=H17,"Equal","Not Equal") -> Equal | L17: =G17-H17 -> 0
B18: =SUMIF(#REF!,#REF!,#REF!) -> #REF! | F18: 45884
B19: =SUMIF(#REF!,#REF!,#REF!) -> #REF! | F19: 45853
B20: =SUMIF(#REF!,#REF!,#REF!) -> #REF! | F20: 45825
B21: =SUMIF(#REF!,#REF!,#REF!) -> #REF! | F21: 45824
B22: =SUMIF(#REF!,#REF!,#REF!) -> #REF! | F22: 45804
B23: =SUMIF(#REF!,#REF!,#REF!) -> #REF! | F23: 45792
B24: =SUMIF(#REF!,#REF!,#REF!) -> #REF! | F24: 45762
B25: =SUMIF(#REF!,#REF!,#REF!) -> #REF! | F25: 45733
B26: =SUMIF(#REF!,#REF!,#REF!) -> #REF! | F26: 45706
B27: =SUMIF(#REF!,#REF!,#REF!) -> #REF! | F27: 45701
B28: =SUMIF(#REF!,#REF!,#REF!) -> #REF! | F28: 45687
B29: =SUMIF(#REF!,#REF!,#REF!) -> #REF! | F29: 45672
... B36: =SUMIF(#REF!,#REF!,#REF!) -> #REF! | F36: 0
B37: =SUMIF(#REF!,#REF!,#REF!) -> #REF!
B38: =SUMIF(#REF!,#REF!,#REF!) -> #REF!
B39: =SUMIF(#REF!,#REF!,#REF!) -> #REF!
B40: =SUMIF(#REF!,#REF!,#REF!) -> #REF!
B41: =SUMIF(#REF!,#REF!,#REF!) -> #REF!
B42: =SUMIF(#REF!,#REF!,#REF!) -> #REF!

Sheet In Process
A1: PATIENTS NAME | B1: Start Date | C1: Submit Date | D1: Projected Reimb | E1: Projected Paid Date | F1: Notes

Sheet Cap
A1: Year | B1: PS&R | C1: Annual Cap | D1: Cap Amount | E1: Total | F1: Actual Cap | G1: Projected Count | H1: Projected Total | I1: Projected Cap | K1: CCN | L1: A11743
A2: 2024 | B2: 8.7699 | C2: 33494.01 | D2: =B2*C2 -> 293739.12 | E2: 291522.68 | F2: =D2-E2 -> 2216.4383
A3: 2025 | B3: 10.9481 | C3: 34465.34 | D3: =B3*C3 -> 377329.99 | E3: 256572.37 | F3: =D3-E3 -> 120757.62
A4: 2026 | B4: 15.6876 | C4: 35361.44 | D4: =B4*C4 -> 554736.13 | E4: 194816.24 | F4: =D4-E4 -> 359919.89
