Workbook

Sheet Claims FY26
A1: PATIENTS NAME | B1: Status | C1: SOC | D1: Paid 1 | E1: Status 1 | F1: Start 2 | G1: Paid 2 | H1: Status 2 | I1: Start 3 | J1: Paid 3 | K1: Status 3 | L1: Start 4 | M1: Paid 4 | N1: Status 4 | O1: Start 5 | P1: Paid 5 | Q1: Status 5 | R1: Start 6 | S1: Paid 6 | T1: Status 6 | U1: Status 7 | V1: HIC/MBI
U2: =IF(OR(E2="a",H2="a",K2="a",N2="a",Q2="a",T2="a"),"a",IF(OR(E2="In Process",H2="In Process",K2="In PRocess",N2="In Process",Q2="In Process",T2="In Process"),"X","")) | V2: 6HT8V20PN53
U3: =IF(OR(E3="a",H3="a",K3="a",N3="a",Q3="a",T3="a"),"a",IF(OR(E3="In Process",H3="In Process",K3="In PRocess",N3="In Process",Q3="In Process",T3="In Process"),"X","")) | V3: 4AT4DA6NP03
U4: =IF(OR(E4="a",H4="a",K4="a",N4="a",Q4="a",T4="a"),"a",IF(OR(E4="In Process",H4="In Process",K4="In PRocess",N4="In Process",Q4="In Process",T4="In Process"),"X","")) | V4: 2QP0MH8FH36
U5: =IF(OR(E5="a",H5="a",K5="a",N5="a",Q5="a",T5="a"),"a",IF(OR(E5="In Process",H5="In Process",K5="In PRocess",N5="In Process",Q5="In Process",T5="In Process"),"X","")) | V5: 7WQ8WM6AX49
U6: =IF(OR(E6="a",H6="a",K6="a",N6="a",Q6="a",T6="a"),"a",IF(OR(E6="In Process",H6="In Process",K6="In PRocess",N6="In Process",Q6="In Process",T6="In Process"),"X","")) | V6: 7QW1VQ9PE20
U7: =IF(OR(E7="a",H7="a",K7="a",N7="a",Q7="a",T7="a"),"a",IF(OR(E7="In Process",H7="In Process",K7="In PRocess",N7="In Process",Q7="In Process",T7="In Process"),"X","")) | V7: 7J80R09CK35
U8: =IF(OR(E8="a",H8="a",K8="a",N8="a",Q8="a",T8="a"),"a",IF(OR(E8="In Process",H8="In Process",K8="In PRocess",N8="In Process",Q8="In Process",T8="In Process"),"X","")) | V8: 3QQ1MT8ER94
U9: =IF(OR(E9="a",H9="a",K9="a",N9="a",Q9="a",T9="a"),"a",IF(OR(E9="In Process",H9="In Process",K9="In PRocess",N9="In Process",Q9="In Process",T9="In Process"),"X","")) | V9: 1F79Y75CU31
U10: =IF(OR(E10="a",H10="a",K10="a",N10="a",Q10="a",T10="a"),"a",IF(OR(E10="In Process",H10="In Process",K10="In PRocess",N10="In Process",Q10="In Process",T10="In Process"),"X","")) | V10: 8YT0CT2EC44
U11: =IF(OR(E11="a",H11="a",K11="a",N11="a",Q11="a",T11="a"),"a",IF(OR(E11="In Process",H11="In Process",K11="In PRocess",N11="In Process",Q11="In Process",T11="In Process"),"X","")) | V11: 5MP2Y03CX88
U12: =IF(OR(E12="a",H12="a",K12="a",N12="a",Q12="a",T12="a"),"a",IF(OR(E12="In Process",H12="In Process",K12="In PRocess",N12="In Process",Q12="In Process",T12="In Process"),"X","")) | V12: 3UW4KQ0NN76
U13: =IF(OR(E13="a",H13="a",K13="a",N13="a",Q13="a",T13="a"),"a",IF(OR(E13="In Process",H13="In Process",K13="In PRocess",N13="In Process",Q13="In Process",T13="In Process"),"X","")) | V13: 5QV1A74DK93
... U49: =IF(OR(E49="a",H49="a",K49="a",N49="a",Q49="a",T49="a"),"a",IF(OR(E49="In Process",H49="In Process",K49="In PRocess",N49="In Process",Q49="In Process",T49="In Process"),"X","")) | V49: 2D39NH5KD34
V50: 2FP7HR1FG74
V51: 6Q33AJ5ED14
V52: 3XF4P81UQ85
V53: 2EN5QC8XW76
V54: 6X31CY7XW19
V55: 9HG3N48DP75
V56: 2KX9TX5YJ14
V57: 9CJ4A03MY74
V58: 7TY8AY8NH44
V59: 8DD0TM7YT45
V60: 3QQ1MT8ER94
V61: 5UF6D59HY42
... V205: 4XC4G77GU95
U206: =IF(OR(E206="a",H206="a",K206="a",N206="a",Q206="a",T206="a"),"a",IF(OR(E206="In Process",H206="In Process",K206="In PRocess",N206="In Process",Q206="In Process",T206="In Process"),"X","")) | V206: 7TY8AY8NH44
U207: =IF(OR(E207="a",H207="a",K207="a",N207="a",Q207="a",T207="a"),"a",IF(OR(E207="In Process",H207="In Process",K207="In PRocess",N207="In Process",Q207="In Process",T207="In Process"),"X","")) | V207: 9DG8PN7VT50
U208: =IF(OR(E208="a",H208="a",K208="a",N208="a",Q208="a",T208="a"),"a",IF(OR(E208="In Process",H208="In Process",K208="In PRocess",N208="In Process",Q208="In Process",T208="In Process"),"X","")) | V208: 7QW1VQ9PE20
U209: =IF(OR(E209="a",H209="a",K209="a",N209="a",Q209="a",T209="a"),"a",IF(OR(E209="In Process",H209="In Process",K209="In PRocess",N209="In Process",Q209="In Process",T209="In Process"),"X","")) | V209: 4NF8QQ3YT27
U210: =IF(OR(E210="a",H210="a",K210="a",N210="a",Q210="a",T210="a"),"a",IF(OR(E210="In Process",H210="In Process",K210="In PRocess",N210="In Process",Q210="In Process",T210="In Process"),"X","")) | V210: 3QX4G53TK85
U211: =IF(OR(E211="a",H211="a",K211="a",N211="a",Q211="a",T211="a"),"a",IF(OR(E211="In Process",H211="In Process",K211="In PRocess",N211="In Process",Q211="In Process",T211="In Process"),"X","")) | V211: 6Q33AJ5ED14
U212: =IF(OR(E212="a",H212="a",K212="a",N212="a",Q212="a",T212="a"),"a",IF(OR(E212="In Process",H212="In Process",K212="In PRocess",N212="In Process",Q212="In Process",T212="In Process"),"X","")) | V212: 8PF2G64RA83
U213: =IF(OR(E213="a",H213="a",K213="a",N213="a",Q213="a",T213="a"),"a",IF(OR(E213="In Process",H213="In Process",K213="In PRocess",N213="In Process",Q213="In Process",T213="In Process"),"X","")) | V213: 2FP7HR1FG74
U214: =IF(OR(E214="a",H214="a",K214="a",N214="a",Q214="a",T214="a"),"a",IF(OR(E214="In Process",H214="In Process",K214="In PRocess",N214="In Process",Q214="In Process",T214="In Process"),"X","")) | V214: 5QV1A74DK93
U215: =IF(OR(E215="a",H215="a",K215="a",N215="a",Q215="a",T215="a"),"a",IF(OR(E215="In Process",H215="In Process",K215="In PRocess",N215="In Process",Q215="In Process",T215="In Process"),"X","")) | V215: 1F79Y75CU31
U216: =IF(OR(E216="a",H216="a",K216="a",N216="a",Q216="a",T216="a"),"a",IF(OR(E216="In Process",H216="In Process",K216="In PRocess",N216="In Process",Q216="In Process",T216="In Process"),"X","")) | V216: 1K89WC2ED58
U217: =IF(OR(E217="a",H217="a",K217="a",N217="a",Q217="a",T217="a"),"a",IF(OR(E217="In Process",H217="In Process",K217="In PRocess",N217="In Process",Q217="In Process",T217="In Process"),"X","")) | V217: 2WX1PP2UV03
... U219: =IF(OR(E219="a",H219="a",K219="a",N219="a",Q219="a",T219="a"),"a",IF(OR(E219="In Process",H219="In Process",K219="In PRocess",N219="In Process",Q219="In Process",T219="In Process"),"X","")) | V219: 1N14KW1RX50
...

Sheet PAYMENTS
A1: DATE | B1: DEPOSIT | C1: AMOUNT | D1: SUSPENSE | E1: TOTAL | F1: NOTES | I1: PAST DUE
A2: November
A3: 45597 | B3: 45601
A4: 45600 | B4: 45602
A5: 45601 | B5: 45603
A6: 45602 | B6: 45604
A7: 45603 | B7: 45607
A8: 45604 | B8: 45608
A9: 45607 | B9: 45609
A10: 45608 | B10: 45610
A11: 45609 | B11: 45611
A12: 45610 | B12: 45614
A13: 45611 | B13: 45615 | C13: 6428.07
A14: 45614 | B14: 45616
A15: 45615 | B15: 45617
A16: 45616 | B16: 45618
A17: 45617 | B17: 45621
A18: 45618 | B18: 45622
A19: 45621 | B19: 45623
A20: 45622 | B20: 45624
A21: 45623 | B21: 45625
A22: 45624 | B22: 45628
A23: 45625 | B23: 45629
A24: Total | C24: =SUM(C3:C23) -> 6428.07
A25: December
A26: 45628 | B26: 45630 | C26: 789.79
A27: 45629 | B27: 45631
A28: 45630 | B28: 45632
A29: 45631 | B29: 45635
A30: 45632 | B30: 45636
A31: 45635 | B31: 45637
A32: 45636 | B32: 45638
A33: 45637 | B33: 45639
A34: 45638 | B34: 45642
A35: 45639 | B35: 45643
A36: 45642 | B36: 45644 | C36: 14118.6
A37: 45643 | B37: 45645
A38: 45644 | B38: 45646
A39: 45645 | B39: 45649 | C39: 1316.32
A40: 45646 | B40: 45650
...

Sheet Payment Summary
A1: PATIENTS NAME | B1: Start Date | C1: Reimb | D1: Paid Date | E1: Notes | F1: HIC/MBI
A2: Swanson, Joy | B2: 3/3/2026 | C2: 6786.06 | D2: 46127 | F2: 1QF1RX0NM02
A3: Echarren, Elena | B3: 3/19/2026 | C3: 3329.55 | D3: 46127 | F3: 9CH0VY4XX23
A4: Gaylard, Phyllis | B4: 3/6/2026 | C4: 6564.34 | D4: 46127 | F4: 6HD7UE9XN71
A5: Kaminsky, Zora | B5: 3/1/2026 | C5: 7939.7 | D5: 46127 | F5: 4PC4VA6QE92
A6: Stone, Marilyn | B6: 3/1/2026 | C6: 7939.7 | D6: 46127 | F6: 1RG3C29WG99
A7: Schifini, Albert | B7: 3/6/2026 | C7: 6301.34 | D7: 46127 | F7: 8FA6A92AA49
A8: Moore, Shirlee | B8: 3/24/2026 | C8: 2048.95 | D8: 46127 | F8: 3CG4Q30XF80
A9: Harris, Charlene | B9: 3/1/2026 | C9: 6691.83 | D9: 46127 | F9: 3GH4H62DE90
A10: Kaminsky, Zora | B10: 2/25/2026 | C10: 1189.52 | D10: 46101 | F10: 4PC4VA6QE92
A11: Stone, Marilyn | B11: 2/28/2026 | C11: 256.12 | D11: 46101 | F11: 1RG3C29WG99
A12: Odie, Carl | B12: 2/20/2026 | C12: 4284.73 | D12: 46097 | F12: 5WX5QY2EP60
A13: Presley, Robert | B13: 2/1/2026 | C13: 5818.64 | D13: 46097 | F13: 7QK4DX2CV02
A14: Cap Repayment | C14: -3020.5 | D14: 46097
A15: Harris, Charlene | B15: 2/1/2026 | C15: 7171.34 | D15: 46097 | F15: 3GH4H62DE90
A16: Gonzalez Suarez, Reyez | B16: 2/1/2026 | C16: 5652.2 | D16: 46097 | F16: 1WC7RT7FE53
A17: Garcia, Davina | B17: 2/1/2026 | C17: 201.86 | D17: 46097 | F17: 3KG3W51ET18
A18: Chriqui, Maurice | B18: 2/1/2026 | C18: 5201.42 | D18: 46097 | F18: 3FM4C63RT62
A19: Crowder, Mary | B19: 2/1/2026 | C19: 6498.1 | D19: 46077 | F19: 4EM1CV3VV34
A20: Crowder, Mary | B20: 1/11/2026 | C20: 4239.15 | D20: 46070 | F20: 4EM1CV3VV34
A21: Harris, Charlene | B21: 1/8/2026 | C21: 6146.86 | D21: 46070 | F21: 3GH4H62DE90
A22: Cap Repayment | C22: -3020.5 | D22: 46070
A23: Chriqui, Maurice | B23: 1/7/2026 | C23: 6402.98 | D23: 46070 | F23: 3FM4C63RT62
A24: Presley, Robert | B24: 1/1/2026 | C24: 6257.79 | D24: 46070 | F24: 7QK4DX2CV02
A25: Gonzalez Suarez, Reyez | B25: 1/11/2026 | C25: 4404.2 | D25: 46070 | F25: 1WC7RT7FE53
A26: Schnabel, Dawn | B26: 1/1/2026 | C26: 3516.25 | D26: 46070 | F26: 7QH2CA8RN15
A27: Wilson, Anthony | B27: 1/1/2026 | C27: 5046.6 | D27: 46070 | F27: 1EP6GW7UD42
A28: Garcia, Davina | B28: 1/1/2026 | C28: 6453.79 | D28: 46070 | F28: 3KG3W51ET18
A29: Stewart, Gary | B29: 12/5/2025 | C29: 1994.93 | D29: 46044 | F29: 1D24QC3CW88
A30: Schnabel, Dawn | B30: 12/1/2025 | C30: 7939.7 | D30: 46038 | F30: 7QH2CA8RN15
A31: Cap Repayment | C31: -3020.5 | D31: 46038
A32: Wilson, Anthony | B32: 12/1/2025 | C32: 6257.79 | D32: 46038 | F32: 1EP6GW7UD42
A33: Presley, Robert | B33: 12/1/2025 | C33: 7879 | D33: 46038 | F33: 7QK4DX2CV02
A34: Garcia, Davina | B34: 12/1/2025 | C34: 6257.79 | D34: 46038 | F34: 3KG3W51ET18
A35: Min, Kyung | B35: 10/13/2025 | C35: -150.56 | D35: 46024 | E35: Adjustment | F35: 2T27G24CF45
A36: Ohkawahira, Hidemi | B36: 10/29/2025 | C36: -26 | D36: 46024 | E36: Adjustment | F36: 5QJ1J63EM25
A37: Garcia, Davina | B37: 10/1/2025 | C37: -254.15 | D37: 46024 | E37: Adjustment | F37: 3KG3W51ET18
A38: Wilson, Anthony | B38: 11/5/2025 | C38: 5248.47 | D38: 46024 | F38: 1EP6GW7UD42
A39: Presley, Robert | B39: 10/29/2025 | C39: -31.17 | D39: 46024 | E39: Adjustment | F39: 7QK4DX2CV02
A40: Haas, Loreen | B40: 10/3/2025 | C40: -100.16 | D40: 46024 | E40: Adjustment | F40: 7PE1XQ3FD04
...

Sheet Future payment
A1: PATIENTS NAME | B1: Start Date | C1: Reimb | D1: Paid Date | E1: Notes | F1: HIC/MBI

Sheet Future Summary
A1: {=_xlfn.UNIQUE('Future payment'!D:D)} -> Paid Date | D1: Status 1 | F1: {=_xlfn.UNIQUE('Payment Summary'!D:D)} -> Paid Date | I1: Status 2
A2: 0 | B2: =SUMIF('Future payment'!D:D,'Future Summary'!A2,'Future payment'!C:C) -> 0 | C2: =VLOOKUP(A2,PAYMENTS!A:D,3,FALSE) -> #N/A | D2: =IF(ISNA(C2),"",IF(B2=C2,"Equal","Not Equal")) | F2: 46127 | G2: =SUMIF('Payment Summary'!D:D,'Future Summary'!F2,'Payment Summary'!C:C) -> 47601.47 | H2: =VLOOKUP(F2,PAYMENTS!A:C,3,FALSE) -> 44580.97 | I2: =IF(G2=H2,"Equal","Not Equal") -> Not Equal | L2: =G2-H2 -> 3020.5
B3: =SUMIF('Future payment'!D:D,'Future Summary'!A3,'Future payment'!C:C) -> 0 | C3: =VLOOKUP(A3,PAYMENTS!A:D,3,FALSE) -> #N/A | D3: =IF(ISNA(C3),"",IF(B3=C3,"Equal","Not Equal")) | F3: 46101 | G3: =SUMIF('Payment Summary'!D:D,'Future Summary'!F3,'Payment Summary'!C:C) -> 1445.64 | H3: =VLOOKUP(F3,PAYMENTS!A:C,3,FALSE) -> 1445.64 | I3: =IF(G3=H3,"Equal","Not Equal") -> Equal | L3: =G3-H3 -> 0
B4: =SUMIF('Future payment'!D:D,'Future Summary'!A4,'Future payment'!C:C) -> 0 | C4: =VLOOKUP(A4,PAYMENTS!A:D,3,FALSE) -> #N/A | D4: =IF(ISNA(C4),"",IF(B4=C4,"Equal","Not Equal")) | F4: 46097 | G4: =SUMIF('Payment Summary'!D:D,'Future Summary'!F4,'Payment Summary'!C:C) -> 25309.69 | H4: =VLOOKUP(F4,PAYMENTS!A:C,3,FALSE) -> 25309.69 | I4: =IF(G4=H4,"Equal","Not Equal") -> Equal | L4: =G4-H4 -> 0
B5: =SUMIF('Future payment'!D:D,'Future Summary'!A5,'Future payment'!C:C) -> 0 | C5: =VLOOKUP(A5,PAYMENTS!A:D,3,FALSE) -> #N/A | D5: =IF(ISNA(C5),"",IF(B5=C5,"Equal","Not Equal")) | F5: 46077 | G5: =SUMIF('Payment Summary'!D:D,'Future Summary'!F5,'Payment Summary'!C:C) -> 6498.1 | H5: =VLOOKUP(F5,PAYMENTS!A:C,3,FALSE) -> 6498.1 | I5: =IF(G5=H5,"Equal","Not Equal") -> Equal | L5: =G5-H5 -> 0
B6: =SUMIF('Future payment'!D:D,'Future Summary'!A6,'Future payment'!C:C) -> 0 | C6: =VLOOKUP(A6,PAYMENTS!A:D,3,FALSE) -> #N/A | D6: =IF(ISNA(C6),"",IF(B6=C6,"Equal","Not Equal")) | F6: 46070 | G6: =SUMIF('Payment Summary'!D:D,'Future Summary'!F6,'Payment Summary'!C:C) -> 39447.12 | H6: =VLOOKUP(F6,PAYMENTS!A:C,3,FALSE) -> 39447.12 | I6: =IF(G6=H6,"Equal","Not Equal") -> Equal | L6: =G6-H6 -> 0
B7: =SUMIF('Future payment'!D:D,'Future Summary'!A7,'Future payment'!C:C) -> 0 | C7: =VLOOKUP(A7,PAYMENTS!A:D,3,FALSE) -> #N/A | D7: =IF(ISNA(C7),"",IF(B7=C7,"Equal","Not Equal")) | F7: 46044 | G7: =SUMIF('Payment Summary'!D:D,'Future Summary'!F7,'Payment Summary'!C:C) -> 1994.93 | H7: =VLOOKUP(F7,PAYMENTS!A:C,3,FALSE) -> 1994.93 | I7: =IF(G7=H7,"Equal","Not Equal") -> Equal | L7: =G7-H7 -> 0
B8: =SUMIF('Future payment'!D:D,'Future Summary'!A8,'Future payment'!C:C) -> 0 | C8: =VLOOKUP(A8,PAYMENTS!A:D,3,FALSE) -> #N/A | D8: =IF(ISNA(C8),"",IF(B8=C8,"Equal","Not Equal")) | F8: 46038 | G8: =SUMIF('Payment Summary'!D:D,'Future Summary'!F8,'Payment Summary'!C:C) -> 25313.78 | H8: =VLOOKUP(F8,PAYMENTS!A:C,3,FALSE) -> 25313.78 | I8: =IF(G8=H8,"Equal","Not Equal") -> Equal | L8: =G8-H8 -> 0
B9: =SUMIF('Future payment'!D:D,'Future Summary'!A9,'Future payment'!C:C) -> 0 | C9: =VLOOKUP(A9,PAYMENTS!A:D,3,FALSE) -> #N/A | D9: =IF(ISNA(C9),"",IF(B9=C9,"Equal","Not Equal")) | F9: 46024 | G9: =SUMIF('Payment Summary'!D:D,'Future Summary'!F9,'Payment Summary'!C:C) -> 4686.43 | H9: =VLOOKUP(F9,PAYMENTS!A:C,3,FALSE) -> 4686.43 | I9: =IF(G9=H9,"Equal","Not Equal") -> Equal | L9: =G9-H9 -> 0
B10: =SUMIF('Future payment'!D:D,'Future Summary'!A10,'Future payment'!C:C) -> 0 | C10: =VLOOKUP(A10,PAYMENTS!A:D,3,FALSE) -> #N/A | D10: =IF(ISNA(C10),"",IF(B10=C10,"Equal","Not Equal")) | F10: 46006 | G10: =SUMIF('Payment Summary'!D:D,'Future Summary'!F10,'Payment Summary'!C:C) -> 15997.7 | H10: =VLOOKUP(F10,PAYMENTS!A:C,3,FALSE) -> 15997.7 | I10: =IF(G10=H10,"Equal","Not Equal") -> Equal | L10: =G10-H10 -> 0
B11: =SUMIF('Future payment'!D:D,'Future Summary'!A11,'Future payment'!C:C) -> 0 | C11: =VLOOKUP(A11,PAYMENTS!A:D,3,FALSE) -> #N/A | D11: =IF(ISNA(C11),"",IF(B11=C11,"Equal","Not Equal")) | F11: 45981 | G11: =SUMIF('Payment Summary'!D:D,'Future Summary'!F11,'Payment Summary'!C:C) -> 799.53 | H11: =VLOOKUP(F11,PAYMENTS!A:C,3,FALSE) -> 799.53 | I11: =IF(G11=H11,"Equal","Not Equal") -> Equal | L11: =G11-H11 -> 0
B12: =SUMIF('Future payment'!D:D,'Future Summary'!A12,'Future payment'!C:C) -> 0 | C12: =VLOOKUP(A12,PAYMENTS!A:D,3,FALSE) -> #N/A | D12: =IF(ISNA(C12),"",IF(B12=C12,"Equal","Not Equal")) | F12: 45979 | G12: =SUMIF('Payment Summary'!D:D,'Future Summary'!F12,'Payment Summary'!C:C) -> 697.5 | H12: =VLOOKUP(F12,PAYMENTS!A:C,3,FALSE) -> 697.5 | I12: =IF(G12=H12,"Equal","Not Equal") -> Equal | L12: =G12-H12 -> 0
B13: =SUMIF('Future payment'!D:D,'Future Summary'!A13,'Future payment'!C:C) -> 0 | C13: =VLOOKUP(A13,PAYMENTS!A:D,3,FALSE) -> #N/A | D13: =IF(ISNA(C13),"",IF(B13=C13,"Equal","Not Equal")) | F13: 45978 | G13: =SUMIF('Payment Summary'!D:D,'Future Summary'!F13,'Payment Summary'!C:C) -> 6511.94 | H13: =VLOOKUP(F13,PAYMENTS!A:C,3,FALSE) -> 6511.94 | I13: =IF(G13=H13,"Equal","Not Equal") -> Equal | L13: =G13-H13 -> 0
B14: =SUMIF('Future payment'!D:D,'Future Summary'!A14,'Future payment'!C:C) -> 0 | C14: =VLOOKUP(A14,PAYMENTS!A:D,3,FALSE) -> #N/A | D14: =IF(ISNA(C14),"",IF(B14=C14,"Equal","Not Equal")) | F14: 45968 | G14: =SUMIF('Payment Summary'!D:D,'Future Summary'!F14,'Payment Summary'!C:C) -> 2569.31 | H14: =VLOOKUP(F14,PAYMENTS!A:C,3,FALSE) -> 2569.31 | I14: =IF(G14=H14,"Equal","Not Equal") -> Equal | L14: =G14-H14 -> 0
... B17: =SUMIF('Future payment'!D:D,'Future Summary'!A17,'Future payment'!C:C) -> 0 | C17: =VLOOKUP(A17,PAYMENTS!A:D,3,FALSE) -> #N/A | D17: =IF(ISNA(C17),"",IF(B17=C17,"Equal","Not Equal")) | F17: 45916 | G17: =SUMIF('Payment Summary'!D:D,'Future Summary'!F17,'Payment Summary'!C:C) -> 13012.47 | H17: =VLOOKUP(F17,PAYMENTS!A:C,3,FALSE) -> 13012.47 | I17: =IF(G17=H17,"Equal","Not Equal") -> Equal | L17: =G17-H17 -> 0
B18: =SUMIF(#REF!,#REF!,#REF!) -> #REF! | F18: 45884
B19: =SUMIF(#REF!,#REF!,#REF!) -> #REF! | F19: 45853
B20: =SUMIF(#REF!,#REF!,#REF!) -> #REF! | F20: 45825
B21: =SUMIF(#REF!,#REF!,#REF!) -> #REF! | F21: 45824
B22: =SUMIF(#REF!,#REF!,#REF!) -> #REF! | F22: 45804
B23: =SUMIF(#REF!,#REF!,#REF!) -> #REF! | F23: 45792
B24: =SUMIF(#REF!,#REF!,#REF!) -> #REF! | F24: 45762
B25: =SUMIF(#REF!,#REF!,#REF!) -> #REF! | F25: 45733
B26: =SUMIF(#REF!,#REF!,#REF!) -> #REF! | F26: 45706
B27: =SUMIF(#REF!,#REF!,#REF!) -> #REF! | F27: 45701
B28: =SUMIF(#REF!,#REF!,#REF!) -> #REF! | F28: 45687
B29: =SUMIF(#REF!,#REF!,#REF!) -> #REF! | F29: 45672
... B36: =SUMIF(#REF!,#REF!,#REF!) -> #REF! | F36: 0
B37: =SUMIF(#REF!,#REF!,#REF!) -> #REF!
B38: =SUMIF(#REF!,#REF!,#REF!) -> #REF!
B39: =SUMIF(#REF!,#REF!,#REF!) -> #REF!
B40: =SUMIF(#REF!,#REF!,#REF!) -> #REF!
B41: =SUMIF(#REF!,#REF!,#REF!) -> #REF!
B42: =SUMIF(#REF!,#REF!,#REF!) -> #REF!

Sheet In Process
A1: PATIENTS NAME | B1: Start Date | C1: Submit Date | D1: Projected Reimb | E1: Projected Paid Date | F1: Notes

Sheet Cap
A1: Year | B1: PS&R | C1: Annual Cap | D1: Cap Amount | E1: Total | F1: Actual Cap | G1: Projected Count | H1: Projected Total | I1: Projected Cap | K1: CCN | L1: A11743
A2: 2024 | B2: 8.7699 | C2: 33494.01 | D2: =B2*C2 -> 293739.12 | E2: 291522.68 | F2: =D2-E2 -> 2216.4383
A3: 2025 | B3: 10.9481 | C3: 34465.34 | D3: =B3*C3 -> 377329.99 | E3: 256572.37 | F3: =D3-E3 -> 120757.62
A4: 2026 | B4: 15.6876 | C4: 35361.44 | D4: =B4*C4 -> 554736.13 | E4: 194816.24 | F4: =D4-E4 -> 359919.89
