Workbook
Name Z_A0CAE20E_9122_4930_BCDD_9DF555004942_.wvu.FilterData: 'Claims FY26'!$A$1:$T$351

Sheet Claims
A1: PATIENTS NAME | B1: Status | C1: SOC | D1: Paid 1 | E1: Status 1 | F1: Start 2 | G1: Paid 2 | H1: Status 2 | I1: Start 3 | J1: Paid 3 | K1: Status 3 | L1: Start 4 | M1: Paid 4 | N1: Status 4 | O1: Start 5 | P1: Paid 5 | Q1: Status 5 | R1: Start 6 | S1: Paid 6 | T1: Status 6 | U1: Status 7 | V1: HIC/MBI
U2: =IF(OR(E2="a",H2="a",K2="a",N2="a",Q2="a",T2="a"),"a",IF(OR(E2="In Process",H2="In Process",K2="In PRocess",N2="In Process",Q2="In Process",T2="In Process"),"X","")) | V2: 6HT8V20PN53
U3: =IF(OR(E3="a",H3="a",K3="a",N3="a",Q3="a",T3="a"),"a",IF(OR(E3="In Process",H3="In Process",K3="In PRocess",N3="In Process",Q3="In Process",T3="In Process"),"X","")) | V3: 4AT4DA6NP03
U4: =IF(OR(E4="a",H4="a",K4="a",N4="a",Q4="a",T4="a"),"a",IF(OR(E4="In Process",H4="In Process",K4="In PRocess",N4="In Process",Q4="In Process",T4="In Process"),"X","")) | V4: 2QP0MH8FH36
U5: =IF(OR(E5="a",H5="a",K5="a",N5="a",Q5="a",T5="a"),"a",IF(OR(E5="In Process",H5="In Process",K5="In PRocess",N5="In Process",Q5="In Process",T5="In Process"),"X","")) | V5: 7WQ8WM6AX49
U6: =IF(OR(E6="a",H6="a",K6="a",N6="a",Q6="a",T6="a"),"a",IF(OR(E6="In Process",H6="In Process",K6="In PRocess",N6="In Process",Q6="In Process",T6="In Process"),"X","")) | V6: 7QW1VQ9PE20
U7: =IF(OR(E7="a",H7="a",K7="a",N7="a",Q7="a",T7="a"),"a",IF(OR(E7="In Process",H7="In Process",K7="In PRocess",N7="In Process",Q7="In Process",T7="In Process"),"X","")) | V7: 7J80R09CK35
U8: =IF(OR(E8="a",H8="a",K8="a",N8="a",Q8="a",T8="a"),"a",IF(OR(E8="In Process",H8="In Process",K8="In PRocess",N8="In Process",Q8="In Process",T8="In Process"),"X","")) | V8: 3QQ1MT8ER94
U9: =IF(OR(E9="a",H9="a",K9="a",N9="a",Q9="a",T9="a"),"a",IF(OR(E9="In Process",H9="In Process",K9="In PRocess",N9="In Process",Q9="In Process",T9="In Process"),"X","")) | V9: 1F79Y75CU31
U10: =IF(OR(E10="a",H10="a",K10="a",N10="a",Q10="a",T10="a"),"a",IF(OR(E10="In Process",H10="In Process",K10="In PRocess",N10="In Process",Q10="In Process",T10="In Process"),"X","")) | V10: 8YT0CT2EC44
U11: =IF(OR(E11="a",H11="a",K11="a",N11="a",Q11="a",T11="a"),"a",IF(OR(E11="In Process",H11="In Process",K11="In PRocess",N11="In Process",Q11="In Process",T11="In Process"),"X","")) | V11: 5MP2Y03CX88
U12: =IF(OR(E12="a",H12="a",K12="a",N12="a",Q12="a",T12="a"),"a",IF(OR(E12="In Process",H12="In Process",K12="In PRocess",N12="In Process",Q12="In Process",T12="In Process"),"X","")) | V12: 3UW4KQ0NN76
U13: =IF(OR(E13="a",H13="a",K13="a",N13="a",Q13="a",T13="a"),"a",IF(OR(E13="In Process",H13="In Process",K13="In PRocess",N13="In Process",Q13="In Process",T13="In Process"),"X","")) | V13: 5QV1A74DK93
... U49: =IF(OR(E49="a",H49="a",K49="a",N49="a",Q49="a",T49="a"),"a",IF(OR(E49="In Process",H49="In Process",K49="In PRocess",N49="In Process",Q49="In Process",T49="In Process"),"X","")) | V49: 2D39NH5KD34
V50: 2FP7HR1FG74
V51: 6Q33AJ5ED14
V52: 3XF4P81UQ85
V53: 2EN5QC8XW76
V54: 6X31CY7XW19
V55: 9HG3N48DP75
V56: 2KX9TX5YJ14
V57: 9CJ4A03MY74
V58: 7TY8AY8NH44
V59: 8DD0TM7YT45
V60: 3QQ1MT8ER94
V61: 5UF6D59HY42
... V205: 4XC4G77GU95
U206: =IF(OR(E206="a",H206="a",K206="a",N206="a",Q206="a",T206="a"),"a",IF(OR(E206="In Process",H206="In Process",K206="In PRocess",N206="In Process",Q206="In Process",T206="In Process"),"X","")) | V206: 7TY8AY8NH44
U207: =IF(OR(E207="a",H207="a",K207="a",N207="a",Q207="a",T207="a"),"a",IF(OR(E207="In Process",H207="In Process",K207="In PRocess",N207="In Process",Q207="In Process",T207="In Process"),"X","")) | V207: 9DG8PN7VT50
U208: =IF(OR(E208="a",H208="a",K208="a",N208="a",Q208="a",T208="a"),"a",IF(OR(E208="In Process",H208="In Process",K208="In PRocess",N208="In Process",Q208="In Process",T208="In Process"),"X","")) | V208: 7QW1VQ9PE20
U209: =IF(OR(E209="a",H209="a",K209="a",N209="a",Q209="a",T209="a"),"a",IF(OR(E209="In Process",H209="In Process",K209="In PRocess",N209="In Process",Q209="In Process",T209="In Process"),"X","")) | V209: 4NF8QQ3YT27
U210: =IF(OR(E210="a",H210="a",K210="a",N210="a",Q210="a",T210="a"),"a",IF(OR(E210="In Process",H210="In Process",K210="In PRocess",N210="In Process",Q210="In Process",T210="In Process"),"X","")) | V210: 3QX4G53TK85
U211: =IF(OR(E211="a",H211="a",K211="a",N211="a",Q211="a",T211="a"),"a",IF(OR(E211="In Process",H211="In Process",K211="In PRocess",N211="In Process",Q211="In Process",T211="In Process"),"X","")) | V211: 6Q33AJ5ED14
U212: =IF(OR(E212="a",H212="a",K212="a",N212="a",Q212="a",T212="a"),"a",IF(OR(E212="In Process",H212="In Process",K212="In PRocess",N212="In Process",Q212="In Process",T212="In Process"),"X","")) | V212: 8PF2G64RA83
U213: =IF(OR(E213="a",H213="a",K213="a",N213="a",Q213="a",T213="a"),"a",IF(OR(E213="In Process",H213="In Process",K213="In PRocess",N213="In Process",Q213="In Process",T213="In Process"),"X","")) | V213: 2FP7HR1FG74
U214: =IF(OR(E214="a",H214="a",K214="a",N214="a",Q214="a",T214="a"),"a",IF(OR(E214="In Process",H214="In Process",K214="In PRocess",N214="In Process",Q214="In Process",T214="In Process"),"X","")) | V214: 5QV1A74DK93
U215: =IF(OR(E215="a",H215="a",K215="a",N215="a",Q215="a",T215="a"),"a",IF(OR(E215="In Process",H215="In Process",K215="In PRocess",N215="In Process",Q215="In Process",T215="In Process"),"X","")) | V215: 1F79Y75CU31
U216: =IF(OR(E216="a",H216="a",K216="a",N216="a",Q216="a",T216="a"),"a",IF(OR(E216="In Process",H216="In Process",K216="In PRocess",N216="In Process",Q216="In Process",T216="In Process"),"X","")) | V216: 1K89WC2ED58
U217: =IF(OR(E217="a",H217="a",K217="a",N217="a",Q217="a",T217="a"),"a",IF(OR(E217="In Process",H217="In Process",K217="In PRocess",N217="In Process",Q217="In Process",T217="In Process"),"X","")) | V217: 2WX1PP2UV03
... U219: =IF(OR(E219="a",H219="a",K219="a",N219="a",Q219="a",T219="a"),"a",IF(OR(E219="In Process",H219="In Process",K219="In PRocess",N219="In Process",Q219="In Process",T219="In Process"),"X","")) | V219: 1N14KW1RX50
...

Sheet PAYMENTS
A1: DATE | B1: DEPOSIT | C1: AMOUNT | D1: SUSPENSE | E1: TOTAL | F1: NOTES | I1: PAST DUE
A2: Total
A3: 46024 | B3: 46028
A4: 46027 | B4: 46029
A5: 46028 | B5: 46030
A6: 46029 | B6: 46031
A7: 46030 | B7: 46034
A8: 46031 | B8: 46035
A9: 46034 | B9: 46036
A10: 46035 | B10: 46037
A11: 46036 | B11: 46038
A12: 46037 | B12: 46042
A13: 46038 | B13: 46043
A14: 46042 | B14: 46044 | C14: 120823.43
A15: 46043 | B15: 46045
A16: 46044 | B16: 46048
A17: 46045 | B17: 46049
A18: 46048 | B18: 46050
A19: 46049 | B19: 46051
A20: 46050 | B20: 46052
A21: 46051 | B21: 46055
A22: 46052 | B22: 46056
A23: Total
A24: 46055 | B24: 46057
A25: 46056 | B25: 46058
A26: 46057 | B26: 46059
A27: 46058 | B27: 46062
A28: 46059 | B28: 46063
A29: 46062 | B29: 46064
A30: 46063 | B30: 46065
A31: 46064 | B31: 46066
A32: 46065 | B32: 46070
A33: 46066 | B33: 46071
A34: 46070 | B34: 46072 | C34: 100038.56
A35: 46071 | B35: 46073 | C35: 5849.83
A36: 46072 | B36: 46076 | C36: 478.83
A37: 46073 | B37: 46077 | C37: 3962.79
A38: 46076 | B38: 46078
A39: 46077 | B39: 46079
A40: 46078 | B40: 46080
...

Sheet Payment Summary
A1: PATIENTS NAME | B1: Start Date | C1: Reimb | D1: Paid Date | E1: Notes | F1: HIC/MBI
A2: Heiser, Leslie | B2: 3/31/2026 | C2: 239.41 | D2: 46134 | F2: 2H27A01VX39
A3: Habashi, Fariborz | B3: 3/1/2026 | C3: 3830.58 | D3: 46134 | F3: 3H87Y48XT31
A4: Garcia, Eugenia | B4: 3/10/2026 | C4: 718.23 | D4: 46134 | F4: 8GP5WF5PC71
A5: Bowers, Nora | B5: 3/1/2026 | C5: 4548.83 | D5: 46134 | F5: 8CV6J99AA84
A6: Hylander, Waldemar | B6: 3/1/2026 | C6: 1197.06 | D6: 46134 | F6: 1H84FG4KU01
A7: Kirker, Petra | B7: 3/27/2026 | C7: 1197.06 | D7: 46132 | F7: 5NK9QX2YN37
A8: White, Judy | B8: 3/18/2026 | C8: 2641.85 | D8: 46129 | F8: 4NE3QA2FV90
A9: Hawkins, Sammie | B9: 3/13/2026 | C9: 3585.38 | D9: 46129 | F9: 3YJ5HA6PX93
A10: Alden, Elena | B10: 3/20/2026 | C10: 2264.45 | D10: 46129 | F10: 1QV4TH9KF79
A11: Scott, Lisa | B11: 3/18/2026 | C11: 2946.11 | D11: 46129 | F11: 6GR5FR9NY81
A12: Porter, Penny | B12: 3/12/2026 | C12: 3774.08 | D12: 46129 | F12: 4TU2GG9PP25
A13: Libersat, Rodney | B13: 3/1/2026 | C13: 5922.74 | D13: 46129 | F13: 8R88XK4UN27
... A50: Syfu, Olga | B50: 3/5/2026 | C50: 5095.01 | D50: 46128 | F50: 9EW2E30VW83
A51: Neitzke, Adrienne | B51: 2/17/2026 | C51: -8545.91 | D51: 46127 | E51: Adjustment | F51: 5WK9RX6FG42
A52: Vance, Jackie | B52: 2/1/2026 | C52: 6224.71 | D52: 46107 | F52: 8VY2M93NA98
A53: Rothenhoefer, Walter | B53: 2/1/2026 | C53: 5283.71 | D53: 46106 | F53: 5YP6EF4TW76
A54: Smith, Clyde | B54: 2/1/2026 | C54: 5283.71 | D54: 46104 | F54: 5AU9VN2YK32
A55: Wenstrom, Adele | B55: 2/27/2026 | C55: 478.83 | D55: 46104 | F55: 3EP0HK3PA49
A56: Sokolowski, Gail | B56: 2/1/2026 | C56: 2453.16 | D56: 46104 | F56: 3A96D95TY77
A57: Frederick, Frances | B57: 2/20/2026 | C57: 2311.51 | D57: 46101 | F57: 2YX4X55TX75
A58: Rodrigues, Victoria | B58: 2/1/2026 | C58: 5283.71 | D58: 46099 | F58: 6H37W44PC33
A59: Ybanez, Antonio | B59: 2/25/2026 | C59: 957.65 | D59: 46099 | F59: 7KM9H00JN30
A60: Beckett, Elizabeth | B60: 2/1/2026 | C60: 5283.71 | D60: 46099 | F60: 5HY2CN7QH14
A61: Creighton, Thomas | B61: 2/27/2026 | C61: 478.83 | D61: 46099 | F61: 3FA2FT9JW06
A62: Porrazzo, James | B62: 2/1/2026 | C62: 5283.71 | D62: 46099 | F62: 6QJ7NX3KR49
A63: Martinez, Maria | B63: 2/27/2026 | C63: 377.41 | D63: 46099 | F63: 5GG6ME2CJ41
... A219: Porrazzo, James | B219: 8/1/2025 | C219: 5759.02 | D219: 45917 | F219: 6QJ7NX3KR49
A220: Goldberg, Joel | B220: 7/1/2025 | C220: 5848.36 | D220: 45915 | E220: Adjustment | F220: 7FT5TF7HE76
A221: Shelmire, Linnette | B221: 7/1/2025 | C221: 5759.02 | D221: 45889 | F221: 7QM1KT2RJ25
A222: Porrazzo, James | B222: 7/1/2025 | C222: 5759.02 | D222: 45889 | F222: 6QJ7NX3KR49
A223: Johnson, Samuel | B223: 7/28/2025 | C223: 943.45 | D223: 45888 | F223: 4MN7V43QA79
A224: Houts, Charles | B224: 7/1/2025 | C224: 7311.72 | D224: 45887 | F224: 9QT2K43QN83
A225: Beckett, Elizabeth | B225: 7/1/2025 | C225: 7311.72 | D225: 45884 | F225: 5HY2CN7QH14
A226: Rodrigues, Victoria | B226: 7/1/2025 | C226: 5759.02 | D226: 45884 | F226: 6H37W44PC33
A227: Powers, Marylouise | B227: 7/1/2025 | C227: 5759.02 | D227: 45884 | F227: 3HD1C20UV97
A228: Anobile Seess, Louise | B228: 7/1/2025 | C228: 5759.02 | D228: 45884 | F228: 9PV1MG9DT00
A229: Smith, Clyde | B229: 7/1/2025 | C229: 5759.02 | D229: 45884 | F229: 5AU9VN2YK32
A230: Birkenmaier, Juliana | B230: 7/1/2025 | C230: 5759.02 | D230: 45884 | F230: 2AX0UJ6XF11
A231: Alex, Barbara | B231: 7/1/2025 | C231: 6259.89 | D231: 45884 | F231: 8KC4M11JT03
...

Sheet Future payment
A1: PATIENTS NAME | B1: Start Date | C1: Reimb | D1: Paid Date | E1: Notes | F1: HIC/MBI
A2: Accardo, Rita | B2: 4/1/2026 | C2: 540.71 | D2: 46146 | F2: 6MJ1MY6JX04

Sheet Future Summary
A1: {=_xlfn.UNIQUE('Future payment'!D:D)} -> Paid Date | D1: Status 1 | F1: {=_xlfn.UNIQUE('Payment Summary'!D:D)} -> Paid Date | I1: Status 2
A2: 46146 | B2: =SUMIF('Future payment'!D:D,'Future Summary'!A2,'Future payment'!C:C) -> 540.71 | C2: =VLOOKUP(A2,PAYMENTS!A:D,3,FALSE) -> 540.71 | D2: =IF(ISNA(C2),"",IF(B2=C2,"Equal","Not Equal")) -> Equal | F2: 46134 | G2: =SUMIF('Payment Summary'!D:D,'Future Summary'!F2,'Payment Summary'!C:C) -> 10534.11 | H2: =VLOOKUP(F2,PAYMENTS!A:C,3,FALSE) -> 10534.11 | I2: =IF(G2=H2,"Equal","Not Equal") -> Equal
A3: 0 | B3: =SUMIF('Future payment'!D:D,'Future Summary'!A3,'Future payment'!C:C) -> 0 | C3: =VLOOKUP(A3,PAYMENTS!A:D,3,FALSE) -> #N/A | D3: =IF(ISNA(C3),"",IF(B3=C3,"Equal","Not Equal")) | F3: 46132 | G3: =SUMIF('Payment Summary'!D:D,'Future Summary'!F3,'Payment Summary'!C:C) -> 1197.06 | H3: =VLOOKUP(F3,PAYMENTS!A:C,3,FALSE) -> 1951.88 | I3: =IF(G3=H3,"Equal","Not Equal") -> Not Equal
B4: =SUMIF('Future payment'!D:D,'Future Summary'!A4,'Future payment'!C:C) -> 0 | C4: =VLOOKUP(A4,PAYMENTS!A:D,3,FALSE) -> #N/A | D4: =IF(ISNA(C4),"",IF(B4=C4,"Equal","Not Equal")) | F4: 46129 | G4: =SUMIF('Payment Summary'!D:D,'Future Summary'!F4,'Payment Summary'!C:C) -> 38824.97 | H4: =VLOOKUP(F4,PAYMENTS!A:C,3,FALSE) -> 38824.97 | I4: =IF(G4=H4,"Equal","Not Equal") -> Equal
B5: =SUMIF('Future payment'!D:D,'Future Summary'!A5,'Future payment'!C:C) -> 0 | C5: =VLOOKUP(A5,PAYMENTS!A:D,3,FALSE) -> #N/A | D5: =IF(ISNA(C5),"",IF(B5=C5,"Equal","Not Equal")) | F5: 46128 | G5: =SUMIF('Payment Summary'!D:D,'Future Summary'!F5,'Payment Summary'!C:C) -> 178360 | H5: =VLOOKUP(F5,PAYMENTS!A:C,3,FALSE) -> 178360 | I5: =IF(G5=H5,"Equal","Not Equal") -> Equal
B6: =SUMIF('Future payment'!D:D,'Future Summary'!A6,'Future payment'!C:C) -> 0 | C6: =VLOOKUP(A6,PAYMENTS!A:D,3,FALSE) -> #N/A | D6: =IF(ISNA(C6),"",IF(B6=C6,"Equal","Not Equal")) | F6: 46127 | G6: =SUMIF('Payment Summary'!D:D,'Future Summary'!F6,'Payment Summary'!C:C) -> -8545.91 | H6: =VLOOKUP(F6,PAYMENTS!A:C,3,FALSE) -> 72.91 | I6: =IF(G6=H6,"Equal","Not Equal") -> Not Equal
B7: =SUMIF('Future payment'!D:D,'Future Summary'!A7,'Future payment'!C:C) -> 0 | C7: =VLOOKUP(A7,PAYMENTS!A:D,3,FALSE) -> #N/A | D7: =IF(ISNA(C7),"",IF(B7=C7,"Equal","Not Equal")) | F7: 46107 | G7: =SUMIF('Payment Summary'!D:D,'Future Summary'!F7,'Payment Summary'!C:C) -> 6224.71 | H7: =VLOOKUP(F7,PAYMENTS!A:C,3,FALSE) -> 6224.71 | I7: =IF(G7=H7,"Equal","Not Equal") -> Equal
B8: =SUMIF('Future payment'!D:D,'Future Summary'!A8,'Future payment'!C:C) -> 0 | C8: =VLOOKUP(A8,PAYMENTS!A:D,3,FALSE) -> #N/A | D8: =IF(ISNA(C8),"",IF(B8=C8,"Equal","Not Equal")) | F8: 46106 | G8: =SUMIF('Payment Summary'!D:D,'Future Summary'!F8,'Payment Summary'!C:C) -> 5283.71 | H8: =VLOOKUP(F8,PAYMENTS!A:C,3,FALSE) -> 5283.71 | I8: =IF(G8=H8,"Equal","Not Equal") -> Equal
B9: =SUMIF('Future payment'!D:D,'Future Summary'!A9,'Future payment'!C:C) -> 0 | C9: =VLOOKUP(A9,PAYMENTS!A:D,3,FALSE) -> #N/A | D9: =IF(ISNA(C9),"",IF(B9=C9,"Equal","Not Equal")) | F9: 46104 | G9: =SUMIF('Payment Summary'!D:D,'Future Summary'!F9,'Payment Summary'!C:C) -> 8215.7 | H9: =VLOOKUP(F9,PAYMENTS!A:C,3,FALSE) -> 8215.7 | I9: =IF(G9=H9,"Equal","Not Equal") -> Equal
B10: =SUMIF('Future payment'!D:D,'Future Summary'!A10,'Future payment'!C:C) -> 0 | C10: =VLOOKUP(A10,PAYMENTS!A:D,3,FALSE) -> #N/A | D10: =IF(ISNA(C10),"",IF(B10=C10,"Equal","Not Equal")) | F10: 46101 | G10: =SUMIF('Payment Summary'!D:D,'Future Summary'!F10,'Payment Summary'!C:C) -> 2311.51 | H10: =VLOOKUP(F10,PAYMENTS!A:C,3,FALSE) -> 2311.51 | I10: =IF(G10=H10,"Equal","Not Equal") -> Equal
B11: =SUMIF('Future payment'!D:D,'Future Summary'!A11,'Future payment'!C:C) -> 0 | C11: =VLOOKUP(A11,PAYMENTS!A:D,3,FALSE) -> #N/A | D11: =IF(ISNA(C11),"",IF(B11=C11,"Equal","Not Equal")) | F11: 46099 | G11: =SUMIF('Payment Summary'!D:D,'Future Summary'!F11,'Payment Summary'!C:C) -> 23410.91 | H11: =VLOOKUP(F11,PAYMENTS!A:C,3,FALSE) -> 23410.91 | I11: =IF(G11=H11,"Equal","Not Equal") -> Equal
B12: =SUMIF('Future payment'!D:D,'Future Summary'!A12,'Future payment'!C:C) -> 0 | C12: =VLOOKUP(A12,PAYMENTS!A:D,3,FALSE) -> #N/A | D12: =IF(ISNA(C12),"",IF(B12=C12,"Equal","Not Equal")) | F12: 46098 | G12: =SUMIF('Payment Summary'!D:D,'Future Summary'!F12,'Payment Summary'!C:C) -> 84840.85 | H12: =VLOOKUP(F12,PAYMENTS!A:C,3,FALSE) -> 84840.85 | I12: =IF(G12=H12,"Equal","Not Equal") -> Equal
B13: =SUMIF('Future payment'!D:D,'Future Summary'!A13,'Future payment'!C:C) -> 0 | C13: =VLOOKUP(A13,PAYMENTS!A:D,3,FALSE) -> #N/A | D13: =IF(ISNA(C13),"",IF(B13=C13,"Equal","Not Equal")) | F13: 46091 | G13: =SUMIF('Payment Summary'!D:D,'Future Summary'!F13,'Payment Summary'!C:C) -> 2264.45 | H13: =VLOOKUP(F13,PAYMENTS!A:C,3,FALSE) -> 2264.45 | I13: =IF(G13=H13,"Equal","Not Equal") -> Equal
B14: =SUMIF('Future payment'!D:D,'Future Summary'!A14,'Future payment'!C:C) -> 0 | C14: =VLOOKUP(A14,PAYMENTS!A:D,3,FALSE) -> #N/A | D14: =IF(ISNA(C14),"",IF(B14=C14,"Equal","Not Equal")) | F14: 46087 | G14: =SUMIF('Payment Summary'!D:D,'Future Summary'!F14,'Payment Summary'!C:C) -> 478.83 | H14: =VLOOKUP(F14,PAYMENTS!A:C,3,FALSE) -> 478.83 | I14: =IF(G14=H14,"Equal","Not Equal") -> Equal
B15: =SUMIF('Future payment'!D:D,'Future Summary'!A15,'Future payment'!C:C) -> 0 | C15: =VLOOKUP(A15,PAYMENTS!A:D,3,FALSE) -> #N/A | D15: =IF(ISNA(C15),"",IF(B15=C15,"Equal","Not Equal")) | F15: 46073 | G15: =SUMIF('Payment Summary'!D:D,'Future Summary'!F15,'Payment Summary'!C:C) -> 3962.79 | H15: =VLOOKUP(F15,PAYMENTS!A:C,3,FALSE) -> 3962.79 | I15: =IF(G15=H15,"Equal","Not Equal") -> Equal
... B17: =SUMIF('Future payment'!D:D,'Future Summary'!A17,'Future payment'!C:C) -> 0 | C17: =VLOOKUP(A17,PAYMENTS!A:D,3,FALSE) -> #N/A | D17: =IF(ISNA(C17),"",IF(B17=C17,"Equal","Not Equal")) | F17: 46071 | G17: =SUMIF('Payment Summary'!D:D,'Future Summary'!F17,'Payment Summary'!C:C) -> 5849.83 | H17: =VLOOKUP(F17,PAYMENTS!A:C,3,FALSE) -> 5849.83 | I17: =IF(G17=H17,"Equal","Not Equal") -> Equal
B18: =SUMIF(#REF!,#REF!,#REF!) -> #REF! | F18: 46070
B19: =SUMIF(#REF!,#REF!,#REF!) -> #REF! | F19: 46042
B20: =SUMIF(#REF!,#REF!,#REF!) -> #REF! | F20: 46020
B21: =SUMIF(#REF!,#REF!,#REF!) -> #REF! | F21: 46008
B22: =SUMIF(#REF!,#REF!,#REF!) -> #REF! | F22: 46007
B23: =SUMIF(#REF!,#REF!,#REF!) -> #REF! | F23: 46000
B24: =SUMIF(#REF!,#REF!,#REF!) -> #REF! | F24: 45992
B25: =SUMIF(#REF!,#REF!,#REF!) -> #REF! | F25: 45980
B26: =SUMIF(#REF!,#REF!,#REF!) -> #REF! | F26: 45979
B27: =SUMIF(#REF!,#REF!,#REF!) -> #REF! | F27: 45953
B28: =SUMIF(#REF!,#REF!,#REF!) -> #REF! | F28: 45951
B29: =SUMIF(#REF!,#REF!,#REF!) -> #REF! | F29: 45946
... B42: =SUMIF(#REF!,#REF!,#REF!) -> #REF! | F42: 45855
F43: 45854
F44: 45853
F45: 45831
F46: 45825
F47: 45817
F48: 45804
F49: 45799
F50: 45793
F51: 45791
F52: 45768
F53: 45765
...

Sheet In Process
A1: PATIENTS NAME | B1: Start Date | C1: Submit Date | D1: Projected Reimb | E1: Projected Paid Date | F1: Notes
A2: Renich, Hazel | B2: 03/26/2026 | C2: 46127 | D2: $1,407.74 | E2: 46141
A3: Blake, Carlos | B3: 03/28/2026 | C3: 46127 | E3: 46141
A4: Colella, Rita | B4: 03/25/2026 | C4: 46127 | E4: 46141
A5: Ybanez, Antonio | B5: 04/01/2026 | C5: 46134 | D5: $2,183.08 | E5: 46148
A6: Weisser, Stephen | B6: 04/01/2026 | C6: 46135 | D6: $184.94 | E6: 46149
A7: Rothenhoefer, Walter | B7: 04/01/2026 | C7: 46135 | D7: $554.80 | E7: 46149

Sheet Cap
A1: Year | B1: PS&R | C1: Annual Cap | D1: Cap Amount | E1: Total | F1: Actual Cap | G1: Projected Count | H1: Projected Total | I1: Projected Cap | K1: CCN | L1: 291663
A2: 2024 | B2: 1.0075 | C2: 33494.01 | D2: =B2*C2 -> 33745.215 | E2: 1800.28 | F2: =D2-E2 -> 31944.935
A3: 2025 | B3: 35.0709 | C3: 34465.34 | D3: =B3*C3 -> 1208730.5 | E3: 882116.11 | F3: =D3-E3 -> 326614.38
A4: 2026 | B4: 42.0797 | C4: 35361.44 | D4: =B4*C4 -> 1487998.8 | E4: 843034.33 | F4: =D4-E4 -> 644964.46

Sheet Claims FY26
A1: PATIENTS NAME | B1: Status | C1: SOC | D1: Paid 1 | E1: Status 1 | F1: Start 2 | G1: Paid 2 | H1: Status 2 | I1: Start 3 | J1: Paid 3 | K1: Status 3 | L1: Start 4 | M1: Paid 4 | N1: Status 4 | O1: Start 5 | P1: Paid 5 | Q1: Status 5 | R1: Start 6 | S1: Paid 6 | T1: Status 6 | U1: Status 7 | V1: HIC/MBI
U2: =IF(OR(E2="a",H2="a",K2="a",N2="a",Q2="a",T2="a"),"a",IF(OR(E2="In Process",H2="In Process",K2="In PRocess",N2="In Process",Q2="In Process",T2="In Process"),"X","")) | V2: 6HT8V20PN53
U3: =IF(OR(E3="a",H3="a",K3="a",N3="a",Q3="a",T3="a"),"a",IF(OR(E3="In Process",H3="In Process",K3="In PRocess",N3="In Process",Q3="In Process",T3="In Process"),"X","")) | V3: 4AT4DA6NP03
U4: =IF(OR(E4="a",H4="a",K4="a",N4="a",Q4="a",T4="a"),"a",IF(OR(E4="In Process",H4="In Process",K4="In PRocess",N4="In Process",Q4="In Process",T4="In Process"),"X","")) | V4: 2QP0MH8FH36
U5: =IF(OR(E5="a",H5="a",K5="a",N5="a",Q5="a",T5="a"),"a",IF(OR(E5="In Process",H5="In Process",K5="In PRocess",N5="In Process",Q5="In Process",T5="In Process"),"X","")) | V5: 7WQ8WM6AX49
U6: =IF(OR(E6="a",H6="a",K6="a",N6="a",Q6="a",T6="a"),"a",IF(OR(E6="In Process",H6="In Process",K6="In PRocess",N6="In Process",Q6="In Process",T6="In Process"),"X","")) | V6: 7QW1VQ9PE20
U7: =IF(OR(E7="a",H7="a",K7="a",N7="a",Q7="a",T7="a"),"a",IF(OR(E7="In Process",H7="In Process",K7="In PRocess",N7="In Process",Q7="In Process",T7="In Process"),"X","")) | V7: 7J80R09CK35
U8: =IF(OR(E8="a",H8="a",K8="a",N8="a",Q8="a",T8="a"),"a",IF(OR(E8="In Process",H8="In Process",K8="In PRocess",N8="In Process",Q8="In Process",T8="In Process"),"X","")) | V8: 3QQ1MT8ER94
U9: =IF(OR(E9="a",H9="a",K9="a",N9="a",Q9="a",T9="a"),"a",IF(OR(E9="In Process",H9="In Process",K9="In PRocess",N9="In Process",Q9="In Process",T9="In Process"),"X","")) | V9: 1F79Y75CU31
U10: =IF(OR(E10="a",H10="a",K10="a",N10="a",Q10="a",T10="a"),"a",IF(OR(E10="In Process",H10="In Process",K10="In PRocess",N10="In Process",Q10="In Process",T10="In Process"),"X","")) | V10: 8YT0CT2EC44
U11: =IF(OR(E11="a",H11="a",K11="a",N11="a",Q11="a",T11="a"),"a",IF(OR(E11="In Process",H11="In Process",K11="In PRocess",N11="In Process",Q11="In Process",T11="In Process"),"X","")) | V11: 5MP2Y03CX88
U12: =IF(OR(E12="a",H12="a",K12="a",N12="a",Q12="a",T12="a"),"a",IF(OR(E12="In Process",H12="In Process",K12="In PRocess",N12="In Process",Q12="In Process",T12="In Process"),"X","")) | V12: 3UW4KQ0NN76
U13: =IF(OR(E13="a",H13="a",K13="a",N13="a",Q13="a",T13="a"),"a",IF(OR(E13="In Process",H13="In Process",K13="In PRocess",N13="In Process",Q13="In Process",T13="In Process"),"X","")) | V13: 5QV1A74DK93
... U49: =IF(OR(E49="a",H49="a",K49="a",N49="a",Q49="a",T49="a"),"a",IF(OR(E49="In Process",H49="In Process",K49="In PRocess",N49="In Process",Q49="In Process",T49="In Process"),"X","")) | V49: 2D39NH5KD34
V50: 2FP7HR1FG74
V51: 6Q33AJ5ED14
V52: 3XF4P81UQ85
V53: 2EN5QC8XW76
V54: 6X31CY7XW19
V55: 9HG3N48DP75
V56: 2KX9TX5YJ14
V57: 9CJ4A03MY74
V58: 7TY8AY8NH44
V59: 8DD0TM7YT45
V60: 3QQ1MT8ER94
V61: 5UF6D59HY42
... V205: 4XC4G77GU95
U206: =IF(OR(E206="a",H206="a",K206="a",N206="a",Q206="a",T206="a"),"a",IF(OR(E206="In Process",H206="In Process",K206="In PRocess",N206="In Process",Q206="In Process",T206="In Process"),"X","")) | V206: 7TY8AY8NH44
U207: =IF(OR(E207="a",H207="a",K207="a",N207="a",Q207="a",T207="a"),"a",IF(OR(E207="In Process",H207="In Process",K207="In PRocess",N207="In Process",Q207="In Process",T207="In Process"),"X","")) | V207: 9DG8PN7VT50
U208: =IF(OR(E208="a",H208="a",K208="a",N208="a",Q208="a",T208="a"),"a",IF(OR(E208="In Process",H208="In Process",K208="In PRocess",N208="In Process",Q208="In Process",T208="In Process"),"X","")) | V208: 7QW1VQ9PE20
U209: =IF(OR(E209="a",H209="a",K209="a",N209="a",Q209="a",T209="a"),"a",IF(OR(E209="In Process",H209="In Process",K209="In PRocess",N209="In Process",Q209="In Process",T209="In Process"),"X","")) | V209: 4NF8QQ3YT27
U210: =IF(OR(E210="a",H210="a",K210="a",N210="a",Q210="a",T210="a"),"a",IF(OR(E210="In Process",H210="In Process",K210="In PRocess",N210="In Process",Q210="In Process",T210="In Process"),"X","")) | V210: 3QX4G53TK85
U211: =IF(OR(E211="a",H211="a",K211="a",N211="a",Q211="a",T211="a"),"a",IF(OR(E211="In Process",H211="In Process",K211="In PRocess",N211="In Process",Q211="In Process",T211="In Process"),"X","")) | V211: 6Q33AJ5ED14
U212: =IF(OR(E212="a",H212="a",K212="a",N212="a",Q212="a",T212="a"),"a",IF(OR(E212="In Process",H212="In Process",K212="In PRocess",N212="In Process",Q212="In Process",T212="In Process"),"X","")) | V212: 8PF2G64RA83
U213: =IF(OR(E213="a",H213="a",K213="a",N213="a",Q213="a",T213="a"),"a",IF(OR(E213="In Process",H213="In Process",K213="In PRocess",N213="In Process",Q213="In Process",T213="In Process"),"X","")) | V213: 2FP7HR1FG74
U214: =IF(OR(E214="a",H214="a",K214="a",N214="a",Q214="a",T214="a"),"a",IF(OR(E214="In Process",H214="In Process",K214="In PRocess",N214="In Process",Q214="In Process",T214="In Process"),"X","")) | V214: 5QV1A74DK93
U215: =IF(OR(E215="a",H215="a",K215="a",N215="a",Q215="a",T215="a"),"a",IF(OR(E215="In Process",H215="In Process",K215="In PRocess",N215="In Process",Q215="In Process",T215="In Process"),"X","")) | V215: 1F79Y75CU31
U216: =IF(OR(E216="a",H216="a",K216="a",N216="a",Q216="a",T216="a"),"a",IF(OR(E216="In Process",H216="In Process",K216="In PRocess",N216="In Process",Q216="In Process",T216="In Process"),"X","")) | V216: 1K89WC2ED58
U217: =IF(OR(E217="a",H217="a",K217="a",N217="a",Q217="a",T217="a"),"a",IF(OR(E217="In Process",H217="In Process",K217="In PRocess",N217="In Process",Q217="In Process",T217="In Process"),"X","")) | V217: 2WX1PP2UV03
... U219: =IF(OR(E219="a",H219="a",K219="a",N219="a",Q219="a",T219="a"),"a",IF(OR(E219="In Process",H219="In Process",K219="In PRocess",N219="In Process",Q219="In Process",T219="In Process"),"X","")) | V219: 1N14KW1RX50
...
